# 天翼云盘签到记录

[![签到状态](https://github.com/shaoxiax/189pan/actions/workflows/main.yml/badge.svg)](https://github.com/shaoxiax/189pan/actions/workflows/main.yml) [![项目主页](https://img.shields.io/badge/GitHub-项目主页-blue?logo=github)](https://github.com/shaoxiax/189pan)

**最后更新:** 2025-09-18 21:40:19 CST

## 快速导航

- 🔄 [查看Action运行记录](https://github.com/shaoxiax/189pan/actions)
- 📋 [查看最新运行](https://github.com/shaoxiax/189pan/actions/runs/17830595557)
- 🏠 [返回项目主页](https://github.com/shaoxiax/189pan)
- ⚙️ [手动触发签到](https://github.com/shaoxiax/189pan/actions/workflows/main.yml)

## 签到详情

# 天翼云盘自动签到抽奖程序

## 执行概览
- **启动时间**: 2025-09-18 21:40:19
- **账户数量**: 3 个

## 账户1
登录过程出错: HTTPSConnectionPool(host='open.e.189.cn', port=443): Max retries exceeded with url: /api/logbox/oauth2/autoLogin.do?appId=cloud&version=v1.1&clientType=20010&format=redirect&paras=750D79467623624FCB7627B42A0CE39DDDEF208E420FDF875DE9066BD802AE69E828757D4F31E05FB6760AFFFE4DAE56CB4B347CD83EB2F90CD853A7F8EBA4FD93CDF67733D35F14B89692D717C7C66D619DB2C25148F3976C3EC483520F7F55BEDE28F5AE9CC8FAF7FF96272B18FE50622C75CD22D1C38A321A27D71D1041C7586017ADB545DD790C77227D975105BF33714CE91984BCF8000BCC46645E3E42B90E8084BF75FFA0D30621DC577AA6E3B1B04F6C89A8AA5E7D61C0BBEC98111D3B44795A0C360DE8C79DB412A484044135BA0DDB2AB347039ED572C32EB66E50F0398506FD7D9CC5E939745D87F5D4049C0DD69B41F7569A5EEC90914926CEAFD7009A11491AC92E8AA3D672049AF174791695FB877DECB1FE9760D45CAC152E03A5C69CE95F9918282959D25E49792C1D1F01C9297CACEE3A3D558985E5F635CB5CFA3C7F1BC5747E52894B1D00B4660038C97CFC45104598829840D9B6B4A22BE226C100E5FE8A36A4847D9FB0536E452CA8C81D31CC2E32C7A7629439D8636FC8AA49CBD8BB7956FF7E0E3844308BF5C990E92EBCC5358839938E6BF5950C3B029B460D53009D5FC63DA4F8B9A25ABAFE3B3D84316C9080F265027AE3ECCA4AEFC8264C739EC6CE39D899ABC7DC61E1CED800494E6A27D41C70241E947B38F5A83D024059E9FEEF7445044D4CA0239191B75F36F2CEF0351B927A3081CD3C3D6FB884F84102F70569B9E7FB57FFAE41A2E2ABC70913A8&sign=D61FAB10DB6DE4EA2B8458352D937520F832B104 (Caused by NewConnectionError('<urllib3.connection.HTTPSConnection object at 0x7f6458f88f90>: Failed to establish a new connection: [Errno 101] Network is unreachable'))
### 执行结果
- **登录状态**: 登录失败
- **签到结果**: 

## 账户2
登录过程出错: HTTPSConnectionPool(host='open.e.189.cn', port=443): Max retries exceeded with url: /api/logbox/oauth2/autoLogin.do?appId=cloud&version=v1.1&clientType=20010&format=redirect&paras=A805C222D92125782E7DEEFBEB426975FE493C17144B530DADAF23FE5BFE98FE137997C59CE0BCE84702B729560A301B2571555F9B1B250BBC8F7E391A46B7F7CB7E57156AB3F3D3C17F19555B0BC45DFAC7AC0FE22151EFCC9F4F4B387A154456BE3E778902E3C3C8FFA9EB724CCB0657FF24C0368B9EE4157BB6996CA31905D90793FFF5E4BA72A8D4447FEA388EBB9087A1A9F8E239B73CC00025A64225CD659A12D011EE6DADB62AE24FDDFC68FD5C9DADD4C6B9002D00073E129D938ABE85752D1BE74B929AAD2E0867EE348C18EA17B189AC98CDDE53239978CCB537BE31A8B682207428692D0F104FE27FDCA116DD0C9F24F93C690E78F8F2AAB63A6E9F6CAD5BCC9EAA9390D594909D09F6FEDEEAC2354D4ABDB8D03D3ED262AECAEB1908A3294F5520156F52EE01A5FF7C5577E047F396064C1888C9D68461BCAFCFD15404B0F46CA8D5C2FD97B4B76B560A3AB253646136CEB5475561B3DF21DF24FD398BBC23BF297029D74E9062FAA2CB86B9AF8506D3ED0D512B611999BF6681D53A0CAEF868AABD63FFC0D5E2FE1FAE34E398A01E0222925DC33377AD6A5E8FA22CE420077EE716A49CE6E6415D0D98805FDFD6378637A6C6CD74B0FE0C992809A0D55B9324912CC8BCFE04CBD34C81F3FE48F1C1B7716DF9CC0F1B98362B39959C1D6DA7FA15C67A91BDE8CA9585C14AA3A81346514293288220D11B2DEFDAC6EFED5BD241919BD6570AF718216F34F8CA01A110DE3B64&sign=0DC545060D170EECE655B4FD060E33D9C8EED09D (Caused by NewConnectionError('<urllib3.connection.HTTPSConnection object at 0x7f6458f94750>: Failed to establish a new connection: [Errno 101] Network is unreachable'))
### 执行结果
- **登录状态**: 登录失败
- **签到结果**: 

## 账户3
登录过程出错: HTTPSConnectionPool(host='open.e.189.cn', port=443): Max retries exceeded with url: /api/logbox/oauth2/autoLogin.do?appId=cloud&version=v1.1&clientType=20010&format=redirect&paras=56A579DC391577AE2DDC6F0AA42769CC9A1B404C74F4697021B07F24411436D2FA76B77C1D8CC847DA3BE193A5E2E1B7AD9307B2B4E4B78B1A4C03CB343E5CED78FCD5D0EB5B5C2CE0F818A08B4A3C6C1B9188975DEEBBA597F154F5E74EFD4290BEE4BDEA0EF4FA0FDB23F2BFFD33CECD462F55B4B7F43E294DAF0E4D2455B3990DBA5FB172DED2139AF2AE9E01CDE67EDB0EE837D762485B1D54C0B992D436BBDB513A92EEC03C0A3E4144C2A2F2AEB4766C92D6A24DFA416751B44A29F4E6BB21A5CDD67751F125A93380B8A64EA51707818057682E028BC1AD74AE2F1C45411EF8813755C6CA71EFF5231111F594A9F458CB2D37E246877937606C624BDA2A1ADADA53F13628BA2F9C2472E55D2451F8AF32E8C23A5F02B256A1C8CC8150F93E06DFF891EC8C9210B7969B4D94E20350E035F8C4B9317A3737EB92D1BB710110968034E71C2CA9C4418D83BD43DF98CA02B4019067729DD87BD89958B23C7F0516299F71FA05EBEEA3C0B2E8C83A4FE42513C135BC6D07CB1D67A9BE1181354A944CCE068D3C82E43BE79A5CCDA03C3CDB4C1ED91775E55A7B9D14FA682E62808709E0AD1ADFE698C14D2BD1380CC064265D296B874389BA32D64ED1BE3CB61C2B6DC209EB7E08437D83241C66B9ED7F560AD800D6F0AF05581E9E939765C2960EDD381044B2AF332EED383279EB65CD3E4135E19FE2A807FC81C050638BE75EDCC3CEEF163ECEC2C87430F662B2C4AF01D6FCA1F760&sign=02841551CA856BF26022D9ABA7B016E1AE5ECA5F (Caused by NewConnectionError('<urllib3.connection.HTTPSConnection object at 0x7f6458f7e850>: Failed to establish a new connection: [Errno 101] Network is unreachable'))
### 执行结果
- **登录状态**: 登录失败
- **签到结果**: 

---
## 执行统计
- **结束时间**: 2025-09-18 21:53:56
- **运行时长**: 817.58 秒

✅ **所有账户处理完成！**
