# 天翼云盘签到记录

[![签到状态](https://github.com/shaoxiax/189pan/actions/workflows/main.yml/badge.svg)](https://github.com/shaoxiax/189pan/actions/workflows/main.yml) [![项目主页](https://img.shields.io/badge/GitHub-项目主页-blue?logo=github)](https://github.com/shaoxiax/189pan)

**最后更新:** 2025-08-22 21:42:03 CST

## 快速导航

- 🔄 [查看Action运行记录](https://github.com/shaoxiax/189pan/actions)
- 📋 [查看最新运行](https://github.com/shaoxiax/189pan/actions/runs/17156921152)
- 🏠 [返回项目主页](https://github.com/shaoxiax/189pan)
- ⚙️ [手动触发签到](https://github.com/shaoxiax/189pan/actions/workflows/main.yml)

## 签到详情

# 天翼云盘自动签到抽奖程序

## 执行概览
- **启动时间**: 2025-08-22 21:42:03
- **账户数量**: 3 个

## 账户1
登录过程出错: HTTPSConnectionPool(host='open.e.189.cn', port=443): Max retries exceeded with url: /api/logbox/oauth2/autoLogin.do?appId=cloud&version=v1.1&clientType=20010&format=redirect&paras=494350D5BF705891F8996603EE688E7D016AFF7B61D8E8BFF7E7EBECCFDD9DDD55415C32B6982C4CCB963B1F94EE4FC03FAA15457369BFCE9E4C6B7BEF7010583917A62849395D58408F468FE8249D431D99EF0BAEF85E8D0C49D7161E0145CD782F3C7DA854BEFB559A2F6BCEB6F638E784F121B3DAA397813023A8C4F19FED63D204B3D9BC349F8BABEFC738576DFCDFD74A7B8901441E9687B43B86DB63C3CA148982CF1FB06B339090D13E16ACE6FBB796CBD175C44A8C4896C31C41B30B898A241D8978BE6AB52DFCF1919D53670B1EB869F07077D216ED63EB570E58B3268CC73CADAEF7989B99A72B0600707337383CF6B167A94846CD46A0EA2E0CB7EB8954BA34999FBF7E10A42A1196E7D83327723F01D4F746DFB9E2F73EE4D3B88AF28E00A9C1BBF6769EAEEB8981319991105C283B32B594CE18C0309FA16EE786B6A5CE9F0FD7655F2561A402B490CF759A8CAAC49E5899FBB158BC918ACB631A6B9C4BA64E8EBF2F46221B9B827984FE4BFC88954AE9956E7E449E0CD3A9642FAD88F1437714E9F3B526E65454E1BB9E525A9D0857BFCC347D7BAF02A7071230D6D89E4D8CEAD60EC6A1AB0095430C3485C9A1D02B8B1818EA8FD21771B60B03DE4B42AA70F3D20D23C55DEB25972BBFD16988CA1C28B6CFC78C4446D59CDF4863B203A9FE938586C1A76B9C5FC3BA0AC147B5CED403731E7D3BECCE5E416AC0CD60AF35B2C12E065CB01F56B93B44E2B5C131868D16F4&sign=AFCAAF12A25983349F2FE60B7CA425935CB12907 (Caused by NewConnectionError('<urllib3.connection.HTTPSConnection object at 0x7f830f610990>: Failed to establish a new connection: [Errno 101] Network is unreachable'))
### 执行结果
- **登录状态**: 登录失败
- **签到结果**: 

## 账户2
登录过程出错: HTTPSConnectionPool(host='open.e.189.cn', port=443): Max retries exceeded with url: /api/logbox/oauth2/autoLogin.do?appId=cloud&version=v1.1&clientType=20010&format=redirect&paras=EE1B003E7E0AFA9E61D141E45C0458F1DE73ED321F6ACFA439D22532DA9BEB286C26E47C4E0E023C9EEA9EB0C356997828CCD8EF56129A5F6FB8C41941E21B0CB7946E061034CC6BB90CE38F4C320664EA871BB1438377AAE416AEA7AF552393F36B4E91B8F5B21F058ECD6323414B600ECC8D565AC459E1B1CF1FE3117733FB614A053E5AF22CD142BBF82070B3502D533F23E88355CB870197915D681C13FB41EAF3500518DAD512826703E561BC24E594935257933DDEC12E5C6E99D8C79370ABB91850D31EA3E7844316D772439909086C1FE026835927D6C1F2ECA7A9B9FC081A09ECE824697E7B347694CA986C1218D1CA75AC12D9EB014BB027C03BB22337D4AA2BBC18DEC5DD37A2B17590AFB59C7CC5DE8FEF2FF77B5FD82F917E5775B739DEAF865AAE65B8B32FB594A911F84412A027DCDDD0D2A16F38F1D45BB3EA5841C3C511E6B755BA50925BF7DE64C9E510F014941D1247CAFFD050C6F45CB00D1B2E25AA426CC467ADDE1C4325C657621270655035BDC1F31CF6A67D7BD29FA40ACAD0458AB71EB64F634F8EEC578A1C7960C2A4359885F649EAAAC7F8311729A7EEA49ACB785ED1D3BE0573341208C9DE7E0C48E2340A10AC1C5199E0621446012393E53479EF0F506434985A36111A546D132B3B382751B6F3AF2483E1326AB99424698CF3F3DCE24659C2AF7060AA07720DA40BB60A726F85DC4F1EF18FF6BD364CF62658D79B813B8E02BF1D8094C587690D420B&sign=63BE5D3392F7D3B0423BB525EFA4A308C5AE15CA (Caused by NewConnectionError('<urllib3.connection.HTTPSConnection object at 0x7f830f6181d0>: Failed to establish a new connection: [Errno 101] Network is unreachable'))
### 执行结果
- **登录状态**: 登录失败
- **签到结果**: 

## 账户3
登录过程出错: HTTPSConnectionPool(host='open.e.189.cn', port=443): Max retries exceeded with url: /api/logbox/oauth2/autoLogin.do?appId=cloud&version=v1.1&clientType=20010&format=redirect&paras=0682E5B5ECE7E77B2B59B180C8D0E47211033661C1F329F71088836931D0F29E34AC61FDAA965FAD300D7B8B2D88EE3AAF04EBAEDA9AD499A10739EEAF08661A859998C97900DFAA392268199FD290CA3D49A51975EE0050AAE5235CDDDC3889ED244751584D5B773A5C77F10A7C42D94949A13FA2866B1D62093FBC0637EC460B371AE17E29D7FC29605FF9781533D1FABFA72118CF80DF15145874ECC4B49B32D677D492DFDDF1D78C13D6548CFC580AFFA948F3D4388ACE0A7B45A2A190164B4FA7A2448C94C786271D25A595304EDD7232DE4BBC8C496A4EBF28BD18A7C5B48415CAED64040B78BE3A045031A15877716DD8A778A08DFEC9DD12859D9A73B9935565393DA0C6889B44A3D352E108C810EA5015E54F118C596993EF9F8EFC2EAED4BEBE67571BA21E0A40D7A1C64AC13FD190CDDED98FD54A71AB7C45839E20E0B00E3753D7076CC208AD5EEEA80CA6D5183E42447865DDA91D65D3A5FF8FD4F6352DE2B994FEA4D706C86E112C04FC68A8AED47FEFC7F4D94CBD1C5254A2D399FB8C1ADA9778F26614E8B9085DACCEE2A6C1A15088FADE7069B7B4BD248A02F44E26E974E68F7B720EC56AA7A06E446BC9624655AA1A4535EB88D20A6CC71DE8EB17B75A8D8D2E3479C0095A881E997B71E29205E8A1A2F00CDEB0606FF3A37A9EBA8EEE9E114527D585BD8A6122818CFA531A8C141778BAB38F87820180AD169765A774A0FCC44A0E7D0CE99A0EA6273EAE755F9892&sign=E08940078B644BB245BB0F89E2D7D75C16A66A03 (Caused by NewConnectionError('<urllib3.connection.HTTPSConnection object at 0x7f830f603690>: Failed to establish a new connection: [Errno 101] Network is unreachable'))
### 执行结果
- **登录状态**: 登录失败
- **签到结果**: 

---
## 执行统计
- **结束时间**: 2025-08-22 21:55:39
- **运行时长**: 815.68 秒

✅ **所有账户处理完成！**
