# 天翼云盘签到记录

[![签到状态](https://github.com/shaoxiax/189pan/actions/workflows/main.yml/badge.svg)](https://github.com/shaoxiax/189pan/actions/workflows/main.yml) [![项目主页](https://img.shields.io/badge/GitHub-项目主页-blue?logo=github)](https://github.com/shaoxiax/189pan)

**最后更新:** 2025-08-09 21:43:12 CST

## 快速导航

- 🔄 [查看Action运行记录](https://github.com/shaoxiax/189pan/actions)
- 📋 [查看最新运行](https://github.com/shaoxiax/189pan/actions/runs/16850019752)
- 🏠 [返回项目主页](https://github.com/shaoxiax/189pan)
- ⚙️ [手动触发签到](https://github.com/shaoxiax/189pan/actions/workflows/main.yml)

## 签到详情

# 天翼云盘自动签到抽奖程序

## 执行概览
- **启动时间**: 2025-08-09 21:43:12
- **账户数量**: 3 个

## 账户1
登录过程出错: HTTPSConnectionPool(host='open.e.189.cn', port=443): Max retries exceeded with url: /api/logbox/oauth2/autoLogin.do?appId=cloud&version=v1.1&clientType=20010&format=redirect&paras=9F04EE5DB74211F6EAAB212935D675424B730AF7802B30DC2007F3EB2BA2D5E214DA27FDF4B5947B6B8C0CF3FB973844EA9A660E7EABA746EC18B659EE8C487482034D112CB978FC8BC690B8634106DEB3D5FF557D0DCB82D3F8125E8A396015542C35EE2A436D8EB0190956446DE184AFEEC19F0BB2CAC4901824D9F306E2BAB4B1FBBD38DF90AF999CE4F293B01513A741AB34EEC6868B43A9483EE368A44FDED7EEEA1E2BDABE85F53D508122B9BFB448AB4FF3B74228E8F9C7824036FD2C381BF3394A14B25EE7D9A89CF8AB14026CE619450D5992942A9424CBBBF61181A19803D523762ECEDE8F65CF7299D96BA9FC0D39D97F7051BD6EAFCFE84D8A96EB5B653FF86C36198FDC85F71B87B1E352539AAA7BFCE4DBF9226A25A11FB97540D1350A4AB567D31F297FA493EAD887E50F3DD5B88EB40C582ADB10DAC4F0FC9A6AC08CC1D615FD35E9E72E8AF927EBF357A7E9D0FFBD8442FF094080589EB8FDC0796E961F7CB1B9F21488AD993DB8902B6FC0875AD4EE59A3E42A0DF991DB87EA5A5E4B5F53F6B1212566ADD5E50675819E22CDC860BC7F8EEC6E1EFAA8CA4577FFBCE426D45EA868A7ADEB6D97FE6C73AFAA145DFA01BB59982B79AE44D6E02F86ACD65C99C38E158B476076BBCDF2DD80CEA7753B6DD49ED4DF2F7685A2E227D6F203B11DE6284DC625ECBFD2DDEED9C926E18CA489DD04A00F2017879BCBA716166B5C77CDFFFCE4D3A52F2DAF853F0C5530A7E6E1&sign=3AAA822EE178C4AD2F3AE26AC2CCD2F2162B6AB2 (Caused by NewConnectionError('<urllib3.connection.HTTPSConnection object at 0x7fc6fffe08d0>: Failed to establish a new connection: [Errno 101] Network is unreachable'))
### 执行结果
- **登录状态**: 登录失败
- **签到结果**: 

## 账户2
登录过程出错: HTTPSConnectionPool(host='open.e.189.cn', port=443): Max retries exceeded with url: /api/logbox/oauth2/autoLogin.do?appId=cloud&version=v1.1&clientType=20010&format=redirect&paras=449CD87C1EE6B26839F7C86298244576AA21C84352FEADABC0CACA29D5C1241B4239A79C69E46B17529ABEFE3B9C3383C9AC520F7D57E8516DEB28057CAB002D0085B9480F56934CC98278C91A33D0AB03AA76152EE4690B61675AFC81ED609459C5566C1179433FF1354060A55162D510DFEF3155F0385AEDA9CD0DC96C13963185FBCD52F608A0F9C1C0C8FF6F66958F788AC250231CB1E6DDDA9797FE296E46166DECC885380EECB8F902E9803B533AF485CE99EDAAD865D57E8447745D68329EBE19DD76B1C9A5279636ED08D8597A67C03A58905E0739B65ED9EA7C4E039D4C6F230EED76862E4A3D6828B863852C6872B8F652E9F3EE5A3245FF15CD472AA34DFEE7E9FA69F1FCFEDEF26476A186F549D50BAB3B382EB0C2DEA5661AABD347340B848530BE6320B4C229B42029BEACF24E8D9D54ED40A7A06CA5CEDD33766EF8164D750A1622E8AB3B511FFA359337720A7F02E9D25CBB2CD9FB71398AD10B1BF3251D54310327DA1334B6676A14DB3F5E099B469AC46EC9CC584C544AB73BC636C1678F3DB229621EC4A22BE92077BDF0E671876FBFBC3722F3B08CC3833D984B6AA5A2D9B8EC43A72628084886A15416E6370339D0A3B1DA1BCFB7B232B5FAEBF49862327B74566CDA7E590381EE79965825E01333FF5A9D6DEA753BB14858397D9EF0412CEE21E00AC0A9FD455891689FE30B886B4D49DA9ABDEBC1E0B15F666BBEEEDA1765598F134A8AF52225C1AAF632B479&sign=816D1EB95520B29E680CA064F2ED0A25AAA16AA5 (Caused by NewConnectionError('<urllib3.connection.HTTPSConnection object at 0x7fc6fffe80d0>: Failed to establish a new connection: [Errno 101] Network is unreachable'))
### 执行结果
- **登录状态**: 登录失败
- **签到结果**: 

## 账户3
登录过程出错: HTTPSConnectionPool(host='open.e.189.cn', port=443): Max retries exceeded with url: /api/logbox/oauth2/autoLogin.do?appId=cloud&version=v1.1&clientType=20010&format=redirect&paras=DFA3063BECEC5159A374A68528BBBB42B3C49F826E164F3E23E6AD7526D6B5AD927D81EF18ABB8465CA3B86F6A1E8DDA8A0B399B01449B57EF8EC648C8499E8A8EC090FA98E94C43F1C147AFFB61EDECBAC0AE209CB398A489BCD834817B07347F0482A79D3300D811BBBA7B047386FBE80B198E1C606A3A16425E881D5F76AE3D64DCE3C55AD927830D0943CD017B17B50E4FF50E7EE41062B2C98040B495564F0D1B162BACB3AFB5B20C4DFD14B03D83387386175705F58D242807218B49B7849F5FF1193C594D9E5CAAF4003C315577EF24E605519F847BF4F9401BF3A2FA6DA10CD1934FBF13CD6272CF3F4C06BAE2A10F5C8281E7C3450AA9B20B7B683D2159D3D578E3DBF266B74365C759E6D6EDCB0F61ED95E1F218175CF94287C2DDDAC8981AB4095054558945E456A71720C29E5F0324474A06B0AC0395461816890329FA4ABC4FC72E5EEB106E72A0E6A93AE9129BD23C6C164861F89618C6F4106DB2644A322A2ACBAA9C626CBB7C0E69B94BB12541C4E2D923D94B20D36B6BF2E583A72BCD2368E8174E2DDEB8B29F60A334301F672AA9D7CABFC4E5677459ECF8AD0B5BBC4C8C6AA2CE11A28AF1572EF84B5FDA79E5CFE846A3A016B6D0EBB9E9CC67195867A13AA4202E60900A18CE1402340D52152719A7D94D1B1F73FD800B5E1501D25D75634CB97E2F09CE4824B72404372BF4EFB12FD38E1EB8AFE6B03462C74563362E5869C542D094766A9EDDDA97D06905F350&sign=060254BEA6094A83A84E3080350BAD0BD528B2D2 (Caused by NewConnectionError('<urllib3.connection.HTTPSConnection object at 0x7fc6fffd3c90>: Failed to establish a new connection: [Errno 101] Network is unreachable'))
### 执行结果
- **登录状态**: 登录失败
- **签到结果**: 

---
## 执行统计
- **结束时间**: 2025-08-09 21:56:44
- **运行时长**: 811.70 秒

✅ **所有账户处理完成！**
