# 天翼云盘签到记录

[![签到状态](https://github.com/shaoxiax/189pan/actions/workflows/main.yml/badge.svg)](https://github.com/shaoxiax/189pan/actions/workflows/main.yml) [![项目主页](https://img.shields.io/badge/GitHub-项目主页-blue?logo=github)](https://github.com/shaoxiax/189pan)

**最后更新:** 2025-08-28 21:42:13 CST

## 快速导航

- 🔄 [查看Action运行记录](https://github.com/shaoxiax/189pan/actions)
- 📋 [查看最新运行](https://github.com/shaoxiax/189pan/actions/runs/17297694924)
- 🏠 [返回项目主页](https://github.com/shaoxiax/189pan)
- ⚙️ [手动触发签到](https://github.com/shaoxiax/189pan/actions/workflows/main.yml)

## 签到详情

# 天翼云盘自动签到抽奖程序

## 执行概览
- **启动时间**: 2025-08-28 21:42:13
- **账户数量**: 3 个

## 账户1
登录过程出错: HTTPSConnectionPool(host='open.e.189.cn', port=443): Max retries exceeded with url: /api/logbox/oauth2/autoLogin.do?appId=cloud&version=v1.1&clientType=20010&format=redirect&paras=A7C10E17E2B042637F89DB53B7C2521A27CFF08343DFB08876610461649C84AA846585A8353198E095DE44D22221A0F1BBAC54EA1ACB48A1D7824DADDA10071956222F546BDDD3F1EE5462DB9CEE9726EC3610D0DC3966363E8038503FAE88E11841F6B07679D98023C65265EF2BC6700C3658CA174DA1C275A3E490B6DDBA3A68D43FB5EE5D82BED0C4B0E3935818C597AF6386A6536E32E79ABFC9580715BCB31B0CFB902AB4902D5C88D32A89009D2354737B579651B3F268F1D201602B83A209ADC15D7EEB226981CE08481A2FAC34BA81A1290F7C21E4C930FB8AD2293D6993B9EF6DDEE51A3582149147F4693A20B5298757458395B6EC0C2F289F345FC55F0C0075FB2E7A31CBA0710E03022580E7D142278E12C39D69DCF1989EA5B186183B2C46463926F381AC13C55FD45360CF38D87E61B6639CB3BAE10D277D6A47BDB92DF257BB0E590D471C71F021C498F5535E80EAAAA96037023998611AD14F9D8DB511FF87AAE0FA6B0D9385FE937826139074F65192B3E78AB8AF18F5D703312E87DF9ADE5C7C54FBBC35DC3EEB33E1793F1C0E07082B162D95AA05A734C57A6D817C7A5D055AEC74A1B8BBB757DF4536BC16B505785CBA0A0ABC27F0860EAE036545B266C85E4EFDE666869F162A6DFF992752653C711A0DE57536077B4A8A265ADAA75AC68519B88DDF0AC43DA091B8D81D154C9644DDE4597EB5FA3239B5153BFC9D80BCD6C8AE38F0976AC1792B9E32EFACB336&sign=26CC02FEFCD1E9C31CF428316C95E1C9E1C846B4 (Caused by NewConnectionError('<urllib3.connection.HTTPSConnection object at 0x7f5ea52a0f10>: Failed to establish a new connection: [Errno 101] Network is unreachable'))
### 执行结果
- **登录状态**: 登录失败
- **签到结果**: 

## 账户2
登录过程出错: HTTPSConnectionPool(host='open.e.189.cn', port=443): Max retries exceeded with url: /api/logbox/oauth2/autoLogin.do?appId=cloud&version=v1.1&clientType=20010&format=redirect&paras=5FA832B5B4299577600704A44C8EB9CC035A44145AA5752E6D7D9DEF236D53EF8A56EFC8FCE71C793A0FC4B3C5A3DABD5F0F83BC0F582F74AF4BDAA09BB99C9BF5094DFA4B48FC716504F9752E15C623BD50D0A3C4753832F96896FB85A45DCF6FF8A0B7EE8F780B0B08F093CC295116BBDD776638C2445D68D90B49D87FADA76F8ADDE445C01CE38C260F5FAE5C5B84A2E53C7369F3F169D83EB4521244C877E1BB07FD30B882CD4EE94CCF1CF52AC870064F87B57CABEDBF7897DD9ABEAE9E5BFBACBE12261448906420E6C9DE3FACEB1B72F063A506BA720706B4CFFEDE3BA493E2DC29D47C04AF829D5A8D387BE79AC17DD411CA25B03C2E91C71CAA6F0C1E6B3C6FAE789F287C317DA2EAF60B3116DA7269D48CAF6C75064C6E5A7E35E75D29F1C58D76A6A619F4C34B8ECAE4A7A02427CA4CDC0E3212201A66BBA91F994B1EC346C97ECA73058CC47AE854BC6F75D1FEFC087C846CAE334907282932718D7FA4F7B3F83529759469795BC93937BCB2E53FFD0DAF70E725CEDEFA99D64C5E17F4787AA84454E77277A1A35A24F22E52E51FC5D54FFF55240AF9A957309046D09EFEACDD8F4EDE99257ADCCB5CBAA355762D668DD585C4186F657BE089904EAAADE81EF8150D9D62C498451E9EFDAEC9CB9C020AE89AD441642FBFE8EC00F8CDEE8E113126E6681366E39C036332560E718814B9382E2A57F37CBEEFF9A1AD66590B3A4D49AC7F991982F5475FB250A99C1363104614&sign=1BE63258EBB54581EC4AB41EAA59D64F07BFCAD7 (Caused by NewConnectionError('<urllib3.connection.HTTPSConnection object at 0x7f5ea52ac750>: Failed to establish a new connection: [Errno 101] Network is unreachable'))
### 执行结果
- **登录状态**: 登录失败
- **签到结果**: 

## 账户3
登录过程出错: HTTPSConnectionPool(host='open.e.189.cn', port=443): Max retries exceeded with url: /api/logbox/oauth2/autoLogin.do?appId=cloud&version=v1.1&clientType=20010&format=redirect&paras=966FA643B00557DD524F138639B436E08559EDF7659AE9A20A2A9B7BF0AA6D9CF4FDB8FFE6891CABA030992069E253B8C038EF5CBBE209AF83A03F9F51204A0DE1BD0A95C47ED5CD1E871403990B6ECFC59C01EF186302307CEFA5AB631DFD8E5790FFFF55678B0306C6F3BA9C1B0C22143B37D8EAC96E726B7BF31C7A5DBD2CFF2A4912F04439553AE02E1FF67602E4E64C4D7A33F0B0C3B762AC075FDD533B122452BCA0169E46BEB602A145FACE2D8DD0D9EC715B62410297DA5E34496D7DBA36395D7B8C7D4694DDBFA463D48B052CEE7EA292F2F41DC79312CE17749B00A2E05BCA642AE2EAF53A8E29BF3F13D76002D72C0CF7792667D7965906E12AADAE756974E832172F0279ACFF734C6D2619051FCA10B42D308ABCDA0257426F4673A39B590171D6BD19ED59808C9DE32693540477FBAA689D58711A6A18F7BB495EA2EB935313C45027C2E75AF1A69DF087244458F44F22EE98FCF9DC0EFC440253488921D7DDBF6A66BDBE73A1F7E4F6B818EBFFE782549B21D1B7B942EF5BA887EEEDECD4FFE36E350F2F59A736A894DCA73A4D738F133DAD9AA8EC5883D957CEA3ADD83C467BD6FAA37B8FAA07615F333CEC98CB2CE01833B49017C0AE08009343E2B457D14CF84BF527DD25355A3E14CF86F1229B8A8AE480124CA4837262F337267A052C07C4294B079541C33364D1F9DAB6BCE71A5FE3DEBF96266E1C66A2C371F9FEA8841B15AD28AADCD8DB5B7915323AB247BA1D&sign=B45211454C7E795BD8B34F9304203869922019F3 (Caused by NewConnectionError('<urllib3.connection.HTTPSConnection object at 0x7f5ea5296a50>: Failed to establish a new connection: [Errno 101] Network is unreachable'))
### 执行结果
- **登录状态**: 登录失败
- **签到结果**: 

---
## 执行统计
- **结束时间**: 2025-08-28 21:55:55
- **运行时长**: 822.45 秒

✅ **所有账户处理完成！**
