# 天翼云盘签到记录

[![签到状态](https://github.com/shaoxiax/189pan/actions/workflows/main.yml/badge.svg)](https://github.com/shaoxiax/189pan/actions/workflows/main.yml) [![项目主页](https://img.shields.io/badge/GitHub-项目主页-blue?logo=github)](https://github.com/shaoxiax/189pan)

**最后更新:** 2025-10-23 21:45:54 CST

## 快速导航

- 🔄 [查看Action运行记录](https://github.com/shaoxiax/189pan/actions)
- 📋 [查看最新运行](https://github.com/shaoxiax/189pan/actions/runs/18750494051)
- 🏠 [返回项目主页](https://github.com/shaoxiax/189pan)
- ⚙️ [手动触发签到](https://github.com/shaoxiax/189pan/actions/workflows/main.yml)

## 签到详情

# 天翼云盘自动签到抽奖程序

## 执行概览
- **启动时间**: 2025-10-23 21:45:54
- **账户数量**: 3 个

## 账户1
登录过程出错: HTTPSConnectionPool(host='open.e.189.cn', port=443): Max retries exceeded with url: /api/logbox/oauth2/autoLogin.do?appId=cloud&version=v1.1&clientType=20010&format=redirect&paras=E56751F1FC0FE6E7D70F2C23444849959BB6FDDE0CB3F803F2781B86FBE4800B93B25D3A3891220A35DC400A73872F876C3C2F4469EF068C6582060E8A3DBC8FDC365A2B286345C1748E10BDB34B27E7E2F711D356790C405A646AF371F5C53C9DFD4DDB8FD3D8961B69790C6F8A163E3B66E8DC4AF2376428DDF9665FD7E540E4BAC9420D1C81555871D04E740F758FE78BF30AFD0126BCDA8A3D2DFA7FEC0F0847D4D2B002927FDD0D0D4353D7A82918B44F4F03F99485227A018D273DEBEFF6685FEA4A511E109A1A72373F14C8C88BC5EB00B809C6C8D523F84FC0271D748E0B00006C8613EA4D646A7EFA1875479E55C9035B07F555B48E865AD6D278BB1713ECB614B9D1A251C188C07251A0A8697ED686A1F050E0585DA8135983D19137CCD1237D43E229203BC69815581901B87C60794105DB2714F0CFA7E6B33BFFC497AE7E0A0F9DF68B1185F2DFD55885EF64C6DA3EC2D9CA4F91D611D0BEDA35E2CBC9183F6B7A1295E5156379578C13A4A86DF21BDBB2742730870C4914F2A4C13BB422B3BFBD7284A60FE0D5295431E18748BDA1BA6F63C0CD9555451007FFF50BA3A77E960BB008CF2D0951A4A7D0905605028D9E6BE455CB144EC9EA65D4FF3E01EC1B4B0F81636C2860733BA090B85BFBFE97986B32854478DAD2E5E4CD953D289EDA30051C3ECD076F55904D48FE81D992B8E560FED464DAE254269CCD52111CFAA88E79D180908A5D30F570B2125BF724E84FE6B8&sign=2C10F2379BCA6746A7F9A1B9A24E10C81141C41B (Caused by NewConnectionError('<urllib3.connection.HTTPSConnection object at 0x7f29551e4d50>: Failed to establish a new connection: [Errno 101] Network is unreachable'))
### 执行结果
- **登录状态**: 登录失败
- **签到结果**: 

## 账户2
登录过程出错: HTTPSConnectionPool(host='open.e.189.cn', port=443): Max retries exceeded with url: /api/logbox/oauth2/autoLogin.do?appId=cloud&version=v1.1&clientType=20010&format=redirect&paras=3AC9A7E9BBFA9B06D2480FD54F8420194A1268C4C9CC09B14974B271EF56E7C6585D316A688C3A4471146E4A2E2D6BB0851093D644D0F115C277CF8C175C1291ADCE62080E5D1653963D582714EA6CEB82A5DD8B1133F15F54E6C91C9048614F8CCB8FF11ECF6BF1C658686399FA171068A4C1D2677934A17B0C87D33EB4253920C5E688DD83307607D6304C2C7E25FF25A4CB629437FDB3B11F377AAD9BB0CBA05CD92D8A42A62112C1B53BE63D47EE288BDCC6654B74675F36B0F5AC3F8E30268E33D02A7AE468C4730D584AA0943A4D9C68E97AA54AC95C9A02789F1CD1D356C702BEF6B4669C98D9892A554F2AF63DD0B5536E1BB65478D244F4F7BF62EF437DE3AB044792BD45509E1102C117A8768DE6AC7211CE936DF06FEA4D3797E902EAD3128633E7564A6CBF943CD6EF86D2D685A54F1CBD4D1F63F5D2779C2AE46E41CAC0EED8849BA2A8AA3037F12288F8194E3FA963821C2B7D7E260CD847B81537894194D8C075F64AE32917F017D0997728DA17768F04D7E550DDB3DA1753F82C42FCA29956EC749F7053ACDC27AA2E9310B26BBED1FCB04042051E8D3F599DC0F1EA6430AAD8401AE0596786A2E3B84892D1F9BAE9CD6021ADA375EFAFC50D2FC8E8891BAD3AE8456CBEB247CDC6BBD7A4700578A106EDCA203AEDD3C053469D429F3A630636AB2284A14EAE9F8D7B26401704D1B061D0B9F0EA484419DA109FC0A7DC587349AFF55A584F5FFAC7A0A422CD08FB9894&sign=A998F4A6DF0FFBB59CD4A872028A082827C4AEA6 (Caused by NewConnectionError('<urllib3.connection.HTTPSConnection object at 0x7f29551f0510>: Failed to establish a new connection: [Errno 101] Network is unreachable'))
### 执行结果
- **登录状态**: 登录失败
- **签到结果**: 

## 账户3
登录过程出错: HTTPSConnectionPool(host='open.e.189.cn', port=443): Max retries exceeded with url: /api/logbox/oauth2/autoLogin.do?appId=cloud&version=v1.1&clientType=20010&format=redirect&paras=23BCB221E6601213FAE47AC38ECC5BEEDF6AA25D6CDA488F5334FE464E577770F0C70AB5624E3850C83AD909F1A808C631F5F1852F3DA750ED70B86C33AE9B607762737B14CD84ED2A8D096D3C077F7C357393335EF639273D803B65CCEEB10EF12D73A7434D78E0AD6AD98F44F924B2FBEAE13440870D768BEF719633A947CA1F5B5D757C966EAEF3BCC4D31CCA1B6EF61610D61AD270AFDE1063FE069EA7167510F3C1369C91C60CD973EF9BC5A0655391E6302F24F760AF7B486998D8AD5CCBE2A2AA3107E2C32AA168E1B20C3D27919046105A6E92B5D7506C0774AD2AD59492FCF6E152D440D12717602205A202929471053F6EC199FCB92E83EAC20EACEBAA709FC8F19A4086608660CAF9486F9CED2C9390818CF622DB9C790AB5EB84396D592D883B0C5B3FBEF8BA490C904DF29EE971375DD239B080C7C5B9BA8C8346A8D49DD013EA4DCC966EE451142D32FD7AF668115DAA4E1E012D858D98A11BEF956F841040FC2C35B62E0C8B9FE4D8396F670117015C9CB073F1488676883A24AB8D6642D94C88175965B6A296A9E1D1A76CC571C0E0E8D45264AC449A7B9A039B80C1F7E506A9E45D0B1A5BA629B042F0DC8EF70874C265B5079A41ED4D4503FF139E42DB6D95C8E4FC04F5EFBF26604E10498EB04872AF4B1F538B1565D802DFEB04B9FB291DC01815FB3F0497A745A6FB920EE9484DDB2B0F4888FAB2B946F6643C0D4545F7A357AE5ACEA1CA13C5D571D5236A9F84&sign=DE64F486E313D1FDD6721998AE011A6B03ACE40D (Caused by NewConnectionError('<urllib3.connection.HTTPSConnection object at 0x7f29551ba790>: Failed to establish a new connection: [Errno 101] Network is unreachable'))
### 执行结果
- **登录状态**: 登录失败
- **签到结果**: 

---
## 执行统计
- **结束时间**: 2025-10-23 21:59:26
- **运行时长**: 812.24 秒

✅ **所有账户处理完成！**
