# 天翼云盘签到记录

[![签到状态](https://github.com/shaoxiax/189pan/actions/workflows/main.yml/badge.svg)](https://github.com/shaoxiax/189pan/actions/workflows/main.yml) [![项目主页](https://img.shields.io/badge/GitHub-项目主页-blue?logo=github)](https://github.com/shaoxiax/189pan)

**最后更新:** 2025-10-25 21:35:32 CST

## 快速导航

- 🔄 [查看Action运行记录](https://github.com/shaoxiax/189pan/actions)
- 📋 [查看最新运行](https://github.com/shaoxiax/189pan/actions/runs/18803806948)
- 🏠 [返回项目主页](https://github.com/shaoxiax/189pan)
- ⚙️ [手动触发签到](https://github.com/shaoxiax/189pan/actions/workflows/main.yml)

## 签到详情

# 天翼云盘自动签到抽奖程序

## 执行概览
- **启动时间**: 2025-10-25 21:35:32
- **账户数量**: 3 个

## 账户1
登录过程出错: HTTPSConnectionPool(host='open.e.189.cn', port=443): Max retries exceeded with url: /api/logbox/oauth2/autoLogin.do?appId=cloud&version=v1.1&clientType=20010&format=redirect&paras=EDE1900937E27EE622513D30AA9F9CFF3437B7CF99CC12D098FD78BC01516474BEE3D8C7876F1E05A11913AD72D6EF2BF096F3717088D12525BA3D5A9F2B19B1534E027B3A383149B9A8CA16EA1F8D8ED6DCD26BC79D6B815E2EB2A6D92B106D68EB16F4EDACE5928E5834C9F7EF238370273C4D58DEE4F46797B637A8B6809F76F708A7837A753FB3FBECC718D95CC97CCD62EFFDE12A9A1EC75FC37023153BC0C8253C165CFB5CE98C9C28D0CE484DB4D1B62AAD4EB035C8D1EFFC46FABF40D35AAE41A98A538AE52B24BC4075C8AA9DD1C2C8D8DAC65FAD955E7619C258C57F2B9E8D3EB5AFBBE444E6662A0C78C96F7F8A153A67BA00EA687D190FDC2FF7602405CE365C7A1540E02DD66C75601179A0122C0E0E89BA93B8D42F7213F009ACEB3E17C5568EDDD3AF6F5CFBD1C10767755E5A1CEFAFA83358FEC967B5E58C4823AA7D8B67D6BFCDEB88DAC07A85E0C0864DC66CA3855A5E83DE91A8543155351B8B67DABD41621AA243580077ACAC764767D83FAD781F287A6EFE7857E91C53536C2940B2E697BC084694B5A4AB2452AB5AF98EF86773B15BBD38AA0BB67280EEA3A7660D12AF7F0DFE54787F4A425E24CA8B3B0316BC35F7C9AD548040A32411109D8E12E0F60904A2F0167A97B4E5428F0C95B47AD8F56EC085D2BE506A84266655EBFC88D74DC8B454E14CCBB34B85C87852C8E488DCD732195745C1FA444CA900A35478F80F1699C6E5D8657B040BE6F4F9F8311A&sign=35F9689635B617A60B599A9C09033B969FFE765A (Caused by NewConnectionError('<urllib3.connection.HTTPSConnection object at 0x7ff76f6c4c10>: Failed to establish a new connection: [Errno 101] Network is unreachable'))
### 执行结果
- **登录状态**: 登录失败
- **签到结果**: 

## 账户2
登录过程出错: HTTPSConnectionPool(host='open.e.189.cn', port=443): Max retries exceeded with url: /api/logbox/oauth2/autoLogin.do?appId=cloud&version=v1.1&clientType=20010&format=redirect&paras=419BED1F5FE79904EA8C797C018B568C58C63A371CF3E1425B7621F375EE835CCAD318559B089C5D24B563841CB0558614F20BA8E0D5B5C331EBA807B144668AEA8FB0D7656CE7F948DAFDD06B7DE2C0D9C937B9479DCDA102657316703F89604935971F5E5C8E67701B2806F2CECAF78BF9632344CFF9069A039F9AE0A477D99B90487848F8FDC2713FC3AC78519428ED1D563564AD5148D3688537DEBA3CC8B2CD9962DACACA4BA55B6BAC335B13BF1AF1B649B57CCC6F2278A53BCFE50DFAD30CF00DDADE9AFCAC2972099A02BBE1650C91D5C477416CB8E150B665D17BF7031D2E20190F315035CE3050B4A923CFF4FB0B3C9C83C4EA02F229EE4ADDCD2763B971F7949E4ABDD2B607E66ABA60F4BCDD7D46831E7C90A21E03161EA7C110AE9800CF91892B4C1BDA2E94F52E855E8C332A829FB4E1824D60052929520415682161DE78775D5A5A14E5C883CC6CC5EB95CE9EBA4E0D05DBEFD183278CB1540565B504AB99FD9AF6D612607FF8AC19D7A5CC8EA8C389DE5838B29301F67E1824A5C64D574912772EEDAF4AC16F0AB141464B19611DFA71CF9F88ECCB461AB438C8AF43846C1F7C647DF6A8EFDFB5BE9A32E1340DD63AC2FC1926747018453DDCA10B8D53900C490AE6C9E45CFFD633E4383F006624842086566FA2F4AB0365DA60DD4682F1216D34B9BC30D387B4C475E63D34BD5E8551D07F79BE671F4FC1DC927722309CC7F7B014944C89F54D93218CAF77F2CF659B&sign=120D218D30E345FD9970EC323D38292924E92C83 (Caused by NewConnectionError('<urllib3.connection.HTTPSConnection object at 0x7ff76f6d0410>: Failed to establish a new connection: [Errno 101] Network is unreachable'))
### 执行结果
- **登录状态**: 登录失败
- **签到结果**: 

## 账户3
登录过程出错: HTTPSConnectionPool(host='open.e.189.cn', port=443): Max retries exceeded with url: /api/logbox/oauth2/autoLogin.do?appId=cloud&version=v1.1&clientType=20010&format=redirect&paras=0BF9C231E76F5FB5ED64003C5C059A34306562475F989D88A5922F69B06DE820CBF7D2665929AC78A11017228B514F02942435DD62DF5CDA5A6AF43B8277FDBBBE14566D475F61E0DA2C8556B7D1FE359009C6340E159FE2A15B7C7D7E9B97EC3B3917DE3F8C6D148411D9E9ADE67FCA32195D630F5975C217496411A0812F019A8E0A02A53DF974227388864036DEB497BD0C822B29C76621E827E0F69C14E39F697FD70E614CE26A1D5EBE2C4C61C50F0BC97183C23F0AA2244352097FCE8AD80ECD5B515D5F9DE73CE724686931F7C86A1013CECA9999D4D57107FAE902C877693C3B2BD89C04C775CE71A8283FDAF1F3FC2D6B1AA633B4B78A9F5F99FE86202D7553A9B6A4EFB39F1ECAC6C4A8E53E1538F6B6F8E44371B2B84702393091E8FDE5AA4B2F581F53695B24627A4CB29F1AFA656FC80CD4A1C021D3802936D5D7EA0BD5A07E9377FCCDA06FCA0E0C688FD0B16755D349F16B9C719C90E05A62D609B4D7BF0D1AEA5531CAD0A97B1606614968912C8B37E2085DF77DDDC07AD601457FE65E62F5F38E8F71E2F1D29E9631332D9C6DE05D350E813D848EB0B00F6ECEBAE3E3B25A915BBBFE6081D660A6946345B61314BDB054134C6156F48A85C4B56968A034FD2337561672D0610784BD34BC2D669F76D6E6AA4276264D888D08D630ED461805E39D8548CB677D95F2F7929D5733CCEEFF9953741DC52EAEAEDA9A9AD1F17013FD5616C279CD131794C00A4D9E48929EE7&sign=08E084E38D09E12CB7E9B65F42AEF4EC9F6B92D9 (Caused by NewConnectionError('<urllib3.connection.HTTPSConnection object at 0x7ff76f69a4d0>: Failed to establish a new connection: [Errno 101] Network is unreachable'))
### 执行结果
- **登录状态**: 登录失败
- **签到结果**: 

---
## 执行统计
- **结束时间**: 2025-10-25 21:49:18
- **运行时长**: 825.81 秒

✅ **所有账户处理完成！**
