# 天翼云盘签到记录

[![签到状态](https://github.com/shaoxiax/189pan/actions/workflows/main.yml/badge.svg)](https://github.com/shaoxiax/189pan/actions/workflows/main.yml) [![项目主页](https://img.shields.io/badge/GitHub-项目主页-blue?logo=github)](https://github.com/shaoxiax/189pan)

**最后更新:** 2025-09-05 18:39:14 CST

## 快速导航

- 🔄 [查看Action运行记录](https://github.com/shaoxiax/189pan/actions)
- 📋 [查看最新运行](https://github.com/shaoxiax/189pan/actions/runs/17490874238)
- 🏠 [返回项目主页](https://github.com/shaoxiax/189pan)
- ⚙️ [手动触发签到](https://github.com/shaoxiax/189pan/actions/workflows/main.yml)

## 签到详情

# 天翼云盘自动签到抽奖程序

## 执行概览
- **启动时间**: 2025-09-05 18:39:14
- **账户数量**: 3 个

## 账户1
登录过程出错: HTTPSConnectionPool(host='open.e.189.cn', port=443): Max retries exceeded with url: /api/logbox/oauth2/autoLogin.do?appId=cloud&version=v1.1&clientType=20010&format=redirect&paras=E7F71A22633438705B205BEBC43E35751584B740797367D8234517CFF476A12D926B1B12C4B42A4BE660283D9C4C285A162F8F8393EB2774BD4962A1986D775E455C3E57D0388002BAB682FC42730BC03EB0431938E8609ED9A7E56142B3058C79A9BAD45768180F024C3F892497315AC78C375A781A717F9BD794C8D4EDC104CA99A38AE50005E166D2BC7D0C0C2367CFF90B2B3EE9DA86A620E61E720FCE7963B42C62ABC54F364824B556E054E06FB68BBA8E9A6C9C6F540960E4F96C2F182B96DAA38DAD3B7CB9C12FCA54B4850F51425E09509990C774267BC274B5EA7FB4DCAE8C829EA6F51BB2E44A95FE85154FA077F7B4C635A3B2F8B0393C949C526B0DFF04DCBD8D12E89B38CAC1CB04E7B4108C29C62E5AD65A4E519A6E4378EA3B4E27790F7EB111BC394E606DAE82B8F7AD07B50432F490F00FA865825E2D45C028C0EFF8562DD3BF36016A4DF489B9C53DB619E7C748607421504B6722395D6D0ACA6C1B86B7924533E126D12ABD2B5F05A1E460CEE3B02C5CAF7F54F570CF52D9E62ED112F9825307DDB05B30491589D516ED94A21DB6BFAB328D8D8A4F096910F1BF30A35D41ED1F1CA866ED3CF3281944482C79594A723AE786D16B3E97E1930882BFC5498C4D2400685D47C1DD2D4F50275D60F1EE7B4B80F7ADA63EDF8D03CC3409A7368CC433778BA503BBC5365E4238476867457B642E143A8ABB70C1A3CD983F5D1685DF0A97A8AF5464BCD957F0C49CB8FE94&sign=B3D82DBEFD93098A1A0FDE8B7D26D777FC13DA0D (Caused by NewConnectionError('<urllib3.connection.HTTPSConnection object at 0x7fc453bd0b10>: Failed to establish a new connection: [Errno 101] Network is unreachable'))
### 执行结果
- **登录状态**: 登录失败
- **签到结果**: 

## 账户2
登录过程出错: HTTPSConnectionPool(host='open.e.189.cn', port=443): Max retries exceeded with url: /api/logbox/oauth2/autoLogin.do?appId=cloud&version=v1.1&clientType=20010&format=redirect&paras=89D12C41B1C2DA5679C9FD40D3E020164277F06EF4CC8829172E33782B443C10FC1B35C8316A35A7647C0BB436AACE2D6F25071F14EF7E1474483E0FAEAA9F8BEA6C43627E89A614174A734910844B5DB6A0F8A8AC595AFC67A49EA733ADD87643FDA29E59882B64FFC87D17A26CD01A91F9461736F85CA07AFE5BB397318AB5929EC2D55ED5147C3697FCC9BB35BFCDA5A17E3DC445788A2F81C10EC348A731BF75C972CBB36225FBE1B4FD8AF913B7B84910DC82CC3A2D7638B2858901BF56B025B5E9B6491DA814B379DCEB395E59CE58682667C27DF3B00D93C252F909E767A26E27A1592BD41C12DAE6052F8673CB4BAF2ED501E4953DFE25F88C4FACD313ECBC6521E51C5FD625CBDD0E5DA8EFF871085EE2C15332E1028D3D5BBA2491207DE26505C0BB58C4D0FDA08001966F5F2D1068B46D420F4DEE2974E8FF1299A1643D86934B1A08388755582432A9501342040981FA5B38B03477BAC665815E11968E4439038E6E87E56E93C3A2716A39546B30843E2E33742919CD3D5C6BCF2FA5DEDB8D405F5217A58919B2F0846587AC7A9A6B00FBEC20C57634BF8DC2DBAFD78F8FB3CB4A6F04CDB58567CB4E390CBFC48AD7B28638B9CA99DB21B40112CA427FE222259F695C429EF24F8D8D6FC58A3BE510139D8C0AE2AC276B4545A7F02411E9FBA98B42912983BDAD4A7004A63092E04B0AD07D07FAEF63F1D60AE21321BF21812FD1009B5149A26452F899B2313DB6ABEE828E&sign=6F51D6B144C377DFA9A617CB347DE29C3726B87D (Caused by NewConnectionError('<urllib3.connection.HTTPSConnection object at 0x7fc453bd8310>: Failed to establish a new connection: [Errno 101] Network is unreachable'))
### 执行结果
- **登录状态**: 登录失败
- **签到结果**: 

## 账户3
登录过程出错: HTTPSConnectionPool(host='open.e.189.cn', port=443): Max retries exceeded with url: /api/logbox/oauth2/autoLogin.do?appId=cloud&version=v1.1&clientType=20010&format=redirect&paras=CFF767B3637C615580DF9115F496A479CFD9B083F36D0189393D110640FF92711F3D27150AAAC22E7CAE98CCD7AEE09F3A9670A94B06FB4D90CBA63B7967BD540B514FE14FDF468A761122A3504E6F10069EFFC0365F64110824B8BE6103820CFC7051DDA261CA9BBD15954915934E82F837E4981449955A124DE6CA30424C537E32EB5E844533134ECC5116E01829BB411068C1C3A1338DB848168AAAEA9FC22E5E8149B7D3881B9104766934F9422CB7A095EF88FE1ED0A535A39C5972971D929BCE82C58AFB003F8FC246B354C16C5F69C309165F73399FB098C234FC74B18231A8CFCF95205C836FFD83AA3EE73F2C3A5EB56B033F4719A25E6998F7A8C6384913AF056CCF7EE8A5B7D60374019AF2DA8F662B3BE90FD4F1758AE65DB3B534FE20A9B3BF5C5845FF77B24D53BA6E117DA4450EC2133ECA7018F4DAF90F3BC2F7C685C51F8DB9EA53B6803D625F61D48C31E13A498F8DCAC7E7D72227CB720FFAFFEA98D43E0DFB2B289A16B0489CBBDFE880A2DD58CE728B3C6D38FB49ACAAD8ECF825F3E20BB06497C00628AC00FF440BDB76B33CE0CDA3F2C888B5E5DBE7BA5E81673EBDA5749E56DBA1E2E208AF681E121D7CE7A3D50E6ABB51D0913CE71502F44D3CE7C1AC7FDA9FCACC77D06AB4547096823AC54AE93A65DB5B084B43067ABB2B69819CFD1CB624D1B608A551772A3EA24A4BFD75D2E07A901537E3A5180752FB564270DAB7C4F3659FBB3FDA5046FF148C4E70&sign=FAD15DBDCA2A242DE6C447963D0BA036DFC04604 (Caused by NewConnectionError('<urllib3.connection.HTTPSConnection object at 0x7fc453bc3910>: Failed to establish a new connection: [Errno 101] Network is unreachable'))
### 执行结果
- **登录状态**: 登录失败
- **签到结果**: 

---
## 执行统计
- **结束时间**: 2025-09-05 18:52:47
- **运行时长**: 812.86 秒

✅ **所有账户处理完成！**
