# 天翼云盘签到记录

[![签到状态](https://github.com/shaoxiax/189pan/actions/workflows/main.yml/badge.svg)](https://github.com/shaoxiax/189pan/actions/workflows/main.yml) [![项目主页](https://img.shields.io/badge/GitHub-项目主页-blue?logo=github)](https://github.com/shaoxiax/189pan)

**最后更新:** 2025-10-16 21:45:15 CST

## 快速导航

- 🔄 [查看Action运行记录](https://github.com/shaoxiax/189pan/actions)
- 📋 [查看最新运行](https://github.com/shaoxiax/189pan/actions/runs/18563408332)
- 🏠 [返回项目主页](https://github.com/shaoxiax/189pan)
- ⚙️ [手动触发签到](https://github.com/shaoxiax/189pan/actions/workflows/main.yml)

## 签到详情

# 天翼云盘自动签到抽奖程序

## 执行概览
- **启动时间**: 2025-10-16 21:45:15
- **账户数量**: 3 个

## 账户1
登录过程出错: HTTPSConnectionPool(host='open.e.189.cn', port=443): Max retries exceeded with url: /api/logbox/oauth2/autoLogin.do?appId=cloud&version=v1.1&clientType=20010&format=redirect&paras=F28B46B8D58A52E242A4DA860CF58CADACCF0E2A8F48FC17519F77A31F9A6C60C62CA01D76913A7CB5603BC411B9EB29E0D279FCCC4C6C4E8618731348D9F4B5BDF8A3F80D0B96950C25DC7AB9F604C3B4BECE603AA40E869233708E549E860AEAA77D4AD386396109996DB6A1EC8B16D5EA1ADC4247BBDAD5CA89A1C7BBC7173A526A45DBBE5A11B18F8C89C06273F4387B9DC28DD050D6FE2C87E05102B2F8554371C3BB64A3ABDED7F9AEB4351D8A4A9CABDCAB377675A963994407AD8E6F095F879F7A962E0A9D59E04B0E2F3CB3E6B6D44771A08694617C6B97808E405B12391378542A3081775047338F142D7493318231D0347E1AB2E85A26A58049C50A9D6F6C351AADFE3061636BC56E4D7CF1915872C0C4D83F85CB136A7ADA47795C2DC4EC20A86F97C4A90325DA95AE7EB0F6B8846F7EE7D2EC71FA201077267113481FB4B0601A1FFDA572DD84D07D277BD542313BDAA636DB9B7CBDCCF1AC05DC7993BE1671E0EDBA1CB6573035D393687A7AD3DD36BBFC6E405CA129ADC3367AD352FBE7A87547F1139374ABA9CE1C74A8C218A7ED8BDA6D4018CB78BA39DD7F745ECD1E522BA47F32FF1CAAA59C0B4A62F2C2968057939A0F2C39BB886F69BFDE7758E666E91DF8117F40C34F14B70ACA1F3DACB21B0E46610593E70D14552C4FCF568E8988BB9B668334F3B2C9EDE5210AD33DF6F0F1C78C594C33C916D097E8E8DD9FC03C7EAD7C471A9800191860636B2C13954B02&sign=5B70D56F8D7B0A32B495DD36CBADB0DDCBCDA92D (Caused by NewConnectionError('<urllib3.connection.HTTPSConnection object at 0x7f1c1fe30cd0>: Failed to establish a new connection: [Errno 101] Network is unreachable'))
### 执行结果
- **登录状态**: 登录失败
- **签到结果**: 

## 账户2
登录过程出错: HTTPSConnectionPool(host='open.e.189.cn', port=443): Max retries exceeded with url: /api/logbox/oauth2/autoLogin.do?appId=cloud&version=v1.1&clientType=20010&format=redirect&paras=5851B52BC4858D47A2A0D34BBB0592700212EACFBAAE19676172A25A5FD64F39B64815467928714EBFB9C79977C6A8664BE1FC8E064D808D149D0ABFBFA53AED8D7CE6B9BE422D92D07136A5B808346E99735AAF3D53F44A3AA13156532E370DFEDBE965787293C637A635B5AAFA9113B0801083179D924BB5164C4BD992B199332C385D8E23E3A49C16F5DCD4DC884BD998A1537CD528DDE1857AE1F555EF233B6E7364C5F1FA96CAC23D14215CAE1051B3304DBDC7F14CED33756B150CDD14D3CE7FF238534729BD761F224512842C96E02371B5DA64814D8772C19B8EB6B8D467B4F40C234C86F94242066C2FFB07ADF2513C1E4BBA8346522C4FC087401C11436C18CEE149EDE7D9D88BA57049B8D67EDF8FB594D85E50F1A55B3A83F885C595EDCC799884EE20FB20B5B327FF94526A9075B06C0C052ED2F0E1147800C6B4B31A697066A3D1C55AAC49A42B699BBEE9DDCDA85CEFF5DA7DBCB1162A57EFADE39DC9ACBB0BFBB1AB875867BF751182CB97081F78BD2A1F12AA5C60A7CE1CC9FEC4E505ABE88ECB73DC4256705B3D7395BF1F353C42947D8E8938A5302D3AD50D1BECF37947439D4E3CC6F0A11415BEEF9E3407DC3206730A7F1127D1DA890B31900B04BBC6BCEF664F552E3CA861AD8B913A7FC694AA1F7FC85459BDF7D3EEB2D7A2F9DE753C142CA85100CA51CD0EB8F568F10B4F1F7D7D1DCF6B67C0D433A25C3F5EF67E4A0F4FDB3F116C05CB3BE50CD58A52C3AB&sign=A2D72C9997EABFAF0A5409E433B04EEA7C0F5299 (Caused by NewConnectionError('<urllib3.connection.HTTPSConnection object at 0x7f1c1fe3c490>: Failed to establish a new connection: [Errno 101] Network is unreachable'))
### 执行结果
- **登录状态**: 登录失败
- **签到结果**: 

## 账户3
登录过程出错: HTTPSConnectionPool(host='open.e.189.cn', port=443): Max retries exceeded with url: /api/logbox/oauth2/autoLogin.do?appId=cloud&version=v1.1&clientType=20010&format=redirect&paras=7650DD28B134F54504A215C142B724958AB83563783301E22FE76C17B3D701E8279BAB0BD742045E5FAE8F045F764FC708432CDB077DACA3250014839F1D333F52D3E1B572FBB86BE8FF3F9CEDE959B6FF0DC8902C22CE253CBEE80A062D53C8628E74DC639C917D5120AB5CAF3E2F04900AFB3711E86FF0DCF110D0588EB629B9F76B7ABBAA643C34264DA730B4871CB37865B8C3846181507C88E362FBCF4E1BAF3D8721CF6E5FC8AEDA4C2FB06C4282A2BEF28E9552BFB5676E44AD41D92456DA08171F1EC7E041CF91EA2394AB462482EC6370B3D838B309F2AAA8ED608DDA0CC21704260BFE1597DED09064270ED1535F9D5AE72A7399B766CB88E67DA9370F454964F0B2ADE510AB73C90C6C2759337B45BC861AF0B15531B3B7E380FAAE1E65CBBDF907F0AED74BFFC3E4C04B636A07B5FC0C3FCDA2E24CB1D56D85D0B0D20544F0461843FBDE1B3BAB3DF380DB33DEC2E37916F2F56636DBCB8822CF3DC2061BD547A489653CA470AEAF5B2A9FC7B61DC0A97EAA68BD95EDE9CE0F84E9183342A146F8D62B55ED7FA1825D2F3015970F509F3FD2460BDC9AC17464D16533F26EC338FE106C18EEFAF461CFDB2A4BE9FDD933861ACDE69CFF2D10FCB503757BCBA07E99AEC2ED1326EE3D1FD25B97C4394A4A5C268E5B21437246DEB233622BC30B188C91A1F45B9BC39E5C5F0873218D8EC842A1F58139EE3933322995ED5B8BE832801CFB74DB839D4A496EC05AC77E20DF159A&sign=D4E3D90ABF541CA19A089BD5DCCD2DF5CF435E52 (Caused by NewConnectionError('<urllib3.connection.HTTPSConnection object at 0x7f1c1fe07fd0>: Failed to establish a new connection: [Errno 101] Network is unreachable'))
### 执行结果
- **登录状态**: 登录失败
- **签到结果**: 

---
## 执行统计
- **结束时间**: 2025-10-16 21:59:03
- **运行时长**: 828.50 秒

✅ **所有账户处理完成！**
