# 天翼云盘签到记录

[![签到状态](https://github.com/shaoxiax/189pan/actions/workflows/main.yml/badge.svg)](https://github.com/shaoxiax/189pan/actions/workflows/main.yml) [![项目主页](https://img.shields.io/badge/GitHub-项目主页-blue?logo=github)](https://github.com/shaoxiax/189pan)

**最后更新:** 2025-10-20 18:41:38 CST

## 快速导航

- 🔄 [查看Action运行记录](https://github.com/shaoxiax/189pan/actions)
- 📋 [查看最新运行](https://github.com/shaoxiax/189pan/actions/runs/18649517138)
- 🏠 [返回项目主页](https://github.com/shaoxiax/189pan)
- ⚙️ [手动触发签到](https://github.com/shaoxiax/189pan/actions/workflows/main.yml)

## 签到详情

# 天翼云盘自动签到抽奖程序

## 执行概览
- **启动时间**: 2025-10-20 18:41:38
- **账户数量**: 3 个

## 账户1
登录过程出错: HTTPSConnectionPool(host='open.e.189.cn', port=443): Max retries exceeded with url: /api/logbox/oauth2/autoLogin.do?appId=cloud&version=v1.1&clientType=20010&format=redirect&paras=32EEB138A4F171F69EE807706B9A758B2609426D1CA748E9BB88FD7356E11F09A15A2BBD51D5D501FC7D124BE7AC300AA408ABB89064B16FA50480D5315BD3BE4232F82C9AFEBE25C767B8883753354B9EB77766CBA484185A92C56E870796CA3442DCF8327970F7EC46FA842E70F607F81E3F40C7CA75F875FBDB56FD8357A88830C95BAA26D84D1A74A254D2C695295CADBD38B7822C7D000787717B7E9041B7AD9757A670C6C1ACEF5286DD9E6D4DF44891B0F35E68DDB8C1CAD863E3AA2C40794C041695A1BF413A210874F4209F7CA773FE265E73EA949832AEE4834E1EC9B847E5DB976B4D9C846FF2214D9DBBFB662289116BA65867A716B17BB348F2186874F7B48CABFFA0343102BE100B29E1DE8E3349851C9784D2DA79557E6214E2A86292CC91363E4A889F53DF3294FDF5B5961897F855063D3405ECBABC82962C9C75F0CDB124D0DC5FE43219FC256E7BFF187979AE7FDFBEE8C32AA574DCCEE5BD4CD671B141E16746E86ADB0B660C7684BCB548387A9C92D5B1626255A3F4DB714985C252EFC5AEC482042076595BE5427A74BD6F34B2327EB7316F25AC4DCB6F22F077A2EFD48554C3D9F6D91BD2F0D4783F8E69E641B242E327C725485FF10030E73C9D315FFB60A9B43B51BF8C23CE63084FC7A64E6A21B260B2B07A0E673088F85C70DF00EEFC2D619B7A9E0AB09EC803D6E1B111EDD578419A3357CC111F7508FD49D1F32E3C3B3B004AF590245EAE8B7E3F8272&sign=2F434F75028790AF599543EC88987E72B858A24D (Caused by NewConnectionError('<urllib3.connection.HTTPSConnection object at 0x7fbdb7a14990>: Failed to establish a new connection: [Errno 101] Network is unreachable'))
### 执行结果
- **登录状态**: 登录失败
- **签到结果**: 

## 账户2
登录过程出错: HTTPSConnectionPool(host='open.e.189.cn', port=443): Max retries exceeded with url: /api/logbox/oauth2/autoLogin.do?appId=cloud&version=v1.1&clientType=20010&format=redirect&paras=7DF5E22EE96238FF7D2E632B0100C5A204B205AC345EFE5C22B1F17F62F75F1074521558332A375AF97DF91B3611F993DC0C0F8BB7D79B7A2196F3CAA3D4CF1D2B6A228173BE6BFAADCEB0D883273993C841FFEB58E5D8251ECD5413451DB98227E97BB0ADDB019C8E22E169BE64A8333CBEE73957625DA54BA65E577BF4BF6E6141C36CE1BE5CD66D85FD801DF508E1C9ACB5A2290784DD5428A21325F2EAFA4EF818CC729031BA40990A1DCEBAD18248A21CDB50AA35B88FD9440A0E7798FBFEC531AEAE837348DF7EEF4C5127548B73322C80C6E9F612B9748A0FEB8C34A47FCF5CDFFE6C489E62DE4A9B3EE22333F7C4E47A5FB8C7033745CCEF4A1B9DB9CFCF8AAA4238A371B5A9D5719E3AA5D818FC427388A30F9593B6FD8752D3767FC50399F284A65825AF9C6FB0C5655828D838D8D3D3091DF45AAD48A4E1EF999A5B2102CD84C1B921195934A5BB3420D71738DB43803DC6C6998170BE07682B02B3AD58B97E67C022905631A86A2D28D44C3F1D0F83011A3E9C1D11A81C0F5D34BFB1E1174AC927F8AD7877AB7AF406706EBF4F3DC3CC7348746DCF19807EE21429F2D4BCEB1EAD211E7751E92FA8210B985C15AB9D5C9D906E36872371B035E4097AC88D31B904C6218F3B787CA3806C8AC77433007EF801E47FE4AB8EB3821DEC2DB749AEA7A42B4B1E755A103003F9E96E374D532344D48D8FEDD0440346ECEA0907FFF032E80AED6F0C2DECED515D993DA717E4905303&sign=B225B8C606F631EE461F74D3B0B78F728F1B12D8 (Caused by NewConnectionError('<urllib3.connection.HTTPSConnection object at 0x7fbdb7a18190>: Failed to establish a new connection: [Errno 101] Network is unreachable'))
### 执行结果
- **登录状态**: 登录失败
- **签到结果**: 

## 账户3
登录过程出错: HTTPSConnectionPool(host='open.e.189.cn', port=443): Max retries exceeded with url: /api/logbox/oauth2/autoLogin.do?appId=cloud&version=v1.1&clientType=20010&format=redirect&paras=0349B6C0BD61BE86D8B027E90AF5DEAE923EE58420B5B5A9E6B9407BD92A6850599B08C8D36148E4A8912D75337E6912142E4915C984545CA62BCC0BBA50115E3EE9F2B7275DD31BE5BFB3FE7E72E3495EAD2220D12556CB703F74943E376C885956A4D5CC221D0E66B1918CD14CA7068B0793C152D2C179B4F9BB527F7EF035657E206A7C4EC69ABADDF173777AFCAACD9B823BE49856F77A1CEA37C0942C6D90D306096704094EA096804352D7F2BB4D8DA41DB7F39C671469BF2A07281D205E7F63E03324ECBA1EABA8ECC537EF82656097221932057234C5A0E9A8E3A95A39DA71AAC537C7A40E37F7E28951C04A31BD1F1CFAB9B46D89691D37771A8D4BDCD3623EA78C3FC330F6CC13CE0061BBF13081FF1989AF39E1AC428FF265D770A9E3B526145BE5D0AF8BB71CFE62AEAD4E197499ED7AEE67FE9C526CD79D96A4299B3DEEE479BE3F33D8AEF0B26F237AB89E0436FEF58CD16F11DF2CAC97CE2389286A40A5AD2474ACD2F57C80557C8DDFCC7DA7FDD874EC36C7E7C4AB6BF5CF626018232D38C577B6B1EA0E862719B47602E7CAD3F2843E075D9FB25A194FE99B50F0074199C3E15AD5FD57A1905ADEA856F7201BFA7C6AAF5207D82243F6A4B14B77FED86EEF56C4040924A02370415AE1E3746A57FEB5223FBD6352B23E240C24219D60D6C525DAD12286273379B6416FCE9343083824A967257F8632FD53199EE683B5D9AA29910854B2853528DBDEEE906F3CBEECD3&sign=C57B413913F64ED9121F039EC151E8F3B3850061 (Caused by NewConnectionError('<urllib3.connection.HTTPSConnection object at 0x7fbdb7a02e90>: Failed to establish a new connection: [Errno 101] Network is unreachable'))
### 执行结果
- **登录状态**: 登录失败
- **签到结果**: 

---
## 执行统计
- **结束时间**: 2025-10-20 18:55:16
- **运行时长**: 818.31 秒

✅ **所有账户处理完成！**
