# 天翼云盘签到记录

[![签到状态](https://github.com/shaoxiax/189pan/actions/workflows/main.yml/badge.svg)](https://github.com/shaoxiax/189pan/actions/workflows/main.yml) [![项目主页](https://img.shields.io/badge/GitHub-项目主页-blue?logo=github)](https://github.com/shaoxiax/189pan)

**最后更新:** 2025-08-30 18:35:45 CST

## 快速导航

- 🔄 [查看Action运行记录](https://github.com/shaoxiax/189pan/actions)
- 📋 [查看最新运行](https://github.com/shaoxiax/189pan/actions/runs/17342737798)
- 🏠 [返回项目主页](https://github.com/shaoxiax/189pan)
- ⚙️ [手动触发签到](https://github.com/shaoxiax/189pan/actions/workflows/main.yml)

## 签到详情

# 天翼云盘自动签到抽奖程序

## 执行概览
- **启动时间**: 2025-08-30 18:35:45
- **账户数量**: 3 个

## 账户1
登录过程出错: HTTPSConnectionPool(host='open.e.189.cn', port=443): Max retries exceeded with url: /api/logbox/oauth2/autoLogin.do?appId=cloud&version=v1.1&clientType=20010&format=redirect&paras=9CE1501C4D0CEBFD069259CC14B8259913F3569AD8C56660A01D3FF77C2C9E808AFA3EF6B5D0F97EB1776C86CC2356BF389E7227A1CA5AAC33E1AF15E40374188BF67DC18ADE6F68B1BA0E7A29BCB84635625CE2E3188D92007A8379BF2BEFFFFBED9696FF1E0542E851E512857AD8744A1CF96A0FE3870C11D6D48DB040A6B7B3E40ED8D2E42EC582D7AE4FF064768C3520D0D447C70BC62DA0B57D3CB23E277B2746B6895427E3740A868E3CCDB9AB9AB00B9B791170F2BF9993E0CC0FB9B94D237124AFB74A595B473391D04398F5CC593C71020F398391C12A5B7DD60CA3EBC3AFF6022A666F1F1B9151405D68EEC49B97DAF8246EC9D2163E4D2E14287C2DE3691293DF9D77E5BDBEBB72B2AAFB4AC2A2797E0EA7989CBE0EE01D11B7C105603EC87571988A5406B8ED10AC985BECA5F956485194BAC552CDBB6130B9802E49917909B9C54C442E7DB1D4C61D63427331F67F8D1B59006519EEA598F2CABCD530BEB0B3E86F19A236FE56CBB517607EFCD5CF6749BA3DA47CEDD56338838FA97E1AC3528EC00D9F37D29CC96ADE710A9667F9BA4EB5F8CEE8CE79F6F8CCCA78D10E66A5498F9191A156B9D382D62B51B13B8A812E12BC3FF7827E482ACBFA78D74B25FC0D030559482C40EF136F7EDF38617E19BADECE271DEA33813055898C908E57F64F02273DA5447A59C9C221C19D85680EEEAD902B5A7B23D3ADD23DD9C3FA9E33736E132A08B7303A46E07FF0E5A8C86369CC&sign=912AF49AA5CE3ED6639D22979A9E85EE9C1DC468 (Caused by NewConnectionError('<urllib3.connection.HTTPSConnection object at 0x7fcd55858a50>: Failed to establish a new connection: [Errno 101] Network is unreachable'))
### 执行结果
- **登录状态**: 登录失败
- **签到结果**: 

## 账户2
登录过程出错: HTTPSConnectionPool(host='open.e.189.cn', port=443): Max retries exceeded with url: /api/logbox/oauth2/autoLogin.do?appId=cloud&version=v1.1&clientType=20010&format=redirect&paras=6A16292AC83732287A58A9276E5A150CEBAE6AC6832C80568ECE642228C4EF468AD71BCE9BB4F6D74DB637C9EE97D05E24F9E73BD396AEEAFB04ECC6A54A53FA325A2D1D6E33AA5D16BE38342CA780C0CAB008F02EA8ABBEF62E7BB36CA9E8BB427C767B30780D382EB636D361EEA943DC4B79562002838A6A7F55462805D102A7CC943EA80E8C818864099B1CF6379282540C82BF9B999D0360BF0AD3C6067BF4CD7193AFFEB36DD5C6FA34EF28589F99691A6B33A6337818F398301D04E8950F83F2609709DA4D0EB34DE6DA2FCBD3E736EABB6C94D7C221682A960FEA834B39E5DB08D2903CC9DE3DFECA9E21D20CE7102AEB496D43A4566571A8ED3E4320AD2BA1B7CB54577F150B5F65FDEBBFCF653356B75985E2044E08EB8268D8FDB648F029D806DE447F289866C6CA861908EC64253121FD9C4CD999E99DC87C7F58F252A11952B1E5113655BE37B37D164EAB3D5AE364F1A61D3CC93DD2C677E8FBEA11A5EF894E73BFE732596C8A9158E0C22AAF825E4501AA4ACE5ED40821C2C43123F732FADCEF72AEEAF0259C48B30C0927E917D7895E0BE03BC023110AD772E6B35CF107D52E654EDF80044D33F66071C985CB4C19BCC979600E06C14693B1F1E6FA7CE6E0AD1A420AB21D71E1F38C0BC9AC1614366AD88BD0FAB69AC6F04C4E5E6153DB47942122A73BB1607DEEA4EC177E58EBB384DA37F4D9B910F3D4EB026D06CA325BC4521167EF29088ADFA54083E29BA159AF23&sign=2992FBE3017B02A755BAFEEE9477BA7073103BC4 (Caused by NewConnectionError('<urllib3.connection.HTTPSConnection object at 0x7fcd55860290>: Failed to establish a new connection: [Errno 101] Network is unreachable'))
### 执行结果
- **登录状态**: 登录失败
- **签到结果**: 

## 账户3
登录过程出错: HTTPSConnectionPool(host='open.e.189.cn', port=443): Max retries exceeded with url: /api/logbox/oauth2/autoLogin.do?appId=cloud&version=v1.1&clientType=20010&format=redirect&paras=8125F6FF737CFD47D6B1B4BE5D8E3C633E5A2F30BE8A645A3C8B25EACE5A286BCE8258DB7F84D3C3B9B45D8C6E689EC60B2CE5A5A90D863459B283E5D15FF740176B960F4B5775254D1CD130C8B746FA92D50B3FE6C91EEFE75B70FB7CB5061C78EACF0D6B839D8B3B6975852215A134E94890BB0915128BF15906FDB5C57ABE0A95A4C614B30B4FA6B8A680E9C67050600E620743AC9C4940A61C0ECFCC822169FB811CBCB48B755B67CC3EC0BAA49297F2A4E1043D6888ABE31C67F2C6D3BA0D2006CC0853DCE8126374699049926DC938ECC5E6E2CBA5B2B71D6F4AABD3459EEFC1BCFC2E41754B82B8A986DFC4A00D4ACE5108BE6716DD4A64A1218A12FDC11170DCE02EC711F6B5EB3AD1AA40BBE63B92B4FED6C8A3409889322DD4B81B4B62293E413BE3C51B465CD511CB3757C323F3149C609C22C290E3C2C3E0FA9B224A7C9EFB2486E72FD2145E7AFB199068E32F4E3ADB5ACA68EF0D431B3B1DF4A428815663F47E138A073221C3EE5488EA27720DC529384126476109C906B711A47A1AF449001A668FFAD929AF7D4158ED7471FA3F73B9B28AFA4B73B5C5DCC4CE79F43DE9C24811827917FD9717F942D30775F3DD06BCE04A57E8836D9D8C3CEFD694A16F31B6D9FD7938256D81EE498EC27430BFC46A78F49AABD794B3676DABEF82587B83479D64FA9032764921787D9E9B7BBC7B3D454CCAA84FAA2CD2A5C4F3E1618E3B923E1AC5267DAC8FC6E937E9A89F26978153&sign=18BEA6573085E322AC410EF3323EE9A5013F38BC (Caused by NewConnectionError('<urllib3.connection.HTTPSConnection object at 0x7fcd5584af90>: Failed to establish a new connection: [Errno 101] Network is unreachable'))
### 执行结果
- **登录状态**: 登录失败
- **签到结果**: 

---
## 执行统计
- **结束时间**: 2025-08-30 18:49:21
- **运行时长**: 815.65 秒

✅ **所有账户处理完成！**
