# 天翼云盘签到记录

[![签到状态](https://github.com/shaoxiax/189pan/actions/workflows/main.yml/badge.svg)](https://github.com/shaoxiax/189pan/actions/workflows/main.yml) [![项目主页](https://img.shields.io/badge/GitHub-项目主页-blue?logo=github)](https://github.com/shaoxiax/189pan)

**最后更新:** 2025-07-20 21:47:47 CST

## 快速导航

- 🔄 [查看Action运行记录](https://github.com/shaoxiax/189pan/actions)
- 📋 [查看最新运行](https://github.com/shaoxiax/189pan/actions/runs/16400569812)
- 🏠 [返回项目主页](https://github.com/shaoxiax/189pan)
- ⚙️ [手动触发签到](https://github.com/shaoxiax/189pan/actions/workflows/main.yml)

## 签到详情

# 天翼云盘自动签到抽奖程序

## 执行概览
- **启动时间**: 2025-07-20 21:47:47
- **账户数量**: 3 个

## 账户1
登录过程出错: HTTPSConnectionPool(host='open.e.189.cn', port=443): Max retries exceeded with url: /api/logbox/oauth2/autoLogin.do?appId=cloud&version=v1.1&clientType=20010&format=redirect&paras=7073DE78E20A95B0340BF94F6C4636A79301524633DCA643D36571AC0C41599F2D7499A6A6E01E542780E0747723FE36E61335A506E9F169264E8EC54B68CF3C9043D9BF200EA38FCAA0BA8475B5487096F9BD345AAC6D05C53D1200364230BFC01F3A99BD4C40BB661E5A5367C5D070CF7BF1D281BC35BA3B04BE85E8417013DE1F0E943F67E0890962835907DEE03BFEE11719BBEB124B113438997E1F03A291B5B89A5F555E4407242FFC833784A6BDF9FD299772C3F714C763A2D64657E6C29BA65C66CD6A3180471D79167B57B02235B14F7F6964B45EB0408F605B26417A5544F9DB20D45069BC107F0BC539CEC4CEDF2781C362C53F3805042A04F1226FAC6E3DAFF0D2972990B1C3C74FB7069AAA55BD909F3A5FC40C9A0EFC4A4DE69EAA5896F11326B7403C48E9195B67BA4656B5215DCE0D7D2F4C1A5074DB17FE69E170C49C1B522763DAFFCD6653CFC139E4D14D291EB4AC39CC29F929E2B1334A9890CFCFC2F9890C66CC00F1454ACCF96232D3BFF4BF04DB14380B578DC18484657D4170C7C1DE801591C0A3E318EF70142243ED469E819FCCF2507FCFEC61FCCF1FB2BA8793C754859E0A5903C69FA5F2F9FBA270AC2E50A986BCB1D6C7020B1B61244C25AB6B2A2068ADCD9A9759B6D4432BB2C9CF455379A2EFF335160201A72B7EBCB82FB91AC0F0708D161752CB6B05634A12EE06240BE6A5CC6CE63D15B3012A2C087A7C8C634154030C4EDB370F274EBCC80684&sign=FBF4BF2E451FFA9E5D0B2A013CFF3D7416D4DD59 (Caused by NewConnectionError('<urllib3.connection.HTTPSConnection object at 0x7f5448934690>: Failed to establish a new connection: [Errno 101] Network is unreachable'))
### 执行结果
- **登录状态**: 登录失败
- **签到结果**: 

## 账户2
登录过程出错: HTTPSConnectionPool(host='open.e.189.cn', port=443): Max retries exceeded with url: /api/logbox/oauth2/autoLogin.do?appId=cloud&version=v1.1&clientType=20010&format=redirect&paras=54845FA2AF158493022A35919755BBFA87475D40D1550E1F645B93363979213D9439166161DA69F6B0BFBEA9DAEBCD26B02E9F6F27736382B1315A1D21B9483401E0EDC1CF076094B473D6FE3AD017834CBC5108541449A84079C4BB634A44C551E962A0BFBD3D46FE29F28829E6C4788E77C09B94190066A2EBE222DB533BC2B991FDA3F037486A8ABB598F2B79D25FCB83E5123AB6623E95872AEAA87EC12ADF831810AF226D736178D7CB222DD3EBA508975708CFE98914F7C13508BBF94BFB23BC4D581A48E0C1F1B8465C7310E990E573B897B2A77902910A4534EF722126A48BBEFD121A52644F53DBA05DCF557789CCD7B4ADCB82234BD4E5811A7E65289BF9582ECC74D72347DBC73A26BEA8C4EA50AB27CEF9D53DF3104B57184C91E2D21FFEEAEE800D543972D844452AB3816B12AF85681A554882E43F48EF6E95A3DD6B988771FDA60CEE82A9D76C6DA395651908B8D424BD6CFF0C69680789424F0A3BBE2B9A9B88379F8B676FA415291FC3E9AD1C53D195886B1DA8B26D73247F36E25C3EF29E2F52E13797F96BF32B10599328C0D392637C6458828E8B1BDA96AF8DB1A43D1CDAB1377F4B70F94D4C758A8782C0BFABFC6CD468C3564744C0C3AAE4547C18B69465565105BB29C645FA2879D295E3EB76C96D537D069556AB69AAB9A56C9A04B4E4EB5BE771F50B5C508DF77BD5735B1ACBC8E3F8719147CA80BE152E829098FD9CE6988D5C80894A203A261CD075F9AC&sign=DF93C1CA3B109038769EE4BA7BFADA8172CB2F38 (Caused by NewConnectionError('<urllib3.connection.HTTPSConnection object at 0x7f5448937e50>: Failed to establish a new connection: [Errno 101] Network is unreachable'))
### 执行结果
- **登录状态**: 登录失败
- **签到结果**: 

## 账户3
登录过程出错: HTTPSConnectionPool(host='open.e.189.cn', port=443): Max retries exceeded with url: /api/logbox/oauth2/autoLogin.do?appId=cloud&version=v1.1&clientType=20010&format=redirect&paras=765E83C0CE867B0DC2590EE7989BA68F7E754BB53FB57CD7B4755FAE24D805917EB555ADEEE6FE22E0B47E069CF5C300E245944C8E9FF18C51046F750C09C69161DA484F2385D1E67E2C1AF695FAF5BD2AD7ABCD8726B437909AF171356BEA6E1E9758B8E955D114BFC4EBB2CBBCC84AA56C4B7EE3673A9252B28B63269C6DFB7FFA1FE6EE4427FB029BCA9D2275B3B93AD9AF5950E5F3B4ED73BE9C255AA925E2C9C36CA9A8B77D40E5C1183D63EC89AC0B11BBE3851FBC08B3103ACEC5651F2E3F67EFE00E5C7323B9F29B94783D5FEDE30F8BFCC50FC00861CD3EAE0C74C06B00609A04382CA20E0C4FCED57268ED2D21A17F15F56A4921E32655CC826DC6729F053E89C72EBE84F2B5ECFF590550505C19916389032402A6AB4D3D1C9D031710520A3E4919D7D815E30A23E8F873782990CA5A1BAB186873A2182D26FD813F0C628FB7E723FB398D70308B6B95A80203DCB49368708FD630B1E103A35E80F1C93E46B53D71A0F4B617D11C1B37375E27F8D5B5B86A4D8BEF7D3A5E28F4C8159600AEF68B1DDE98FB34E4DFD860F70EDF24ECCC5F5CBCCFAF49D74BF6579B808745B07CA218D8526D83ABF327F55E3939A0242622D5A78415FD66BF3573EBDCF1CF1EC6EE3F72364862A343DC501338917AD6A0EA4556ACDFE94A05A134247E21A11AE9486F5DA0E6B26825C14B776ADC0C9538DC71F2F9FCF5E8AEA098D332E57CC4736C89BCCA728930C1DE5B89F3FE0940D5AA1099&sign=393CCD701BB90FE459387D32EAA5E689334584A1 (Caused by NewConnectionError('<urllib3.connection.HTTPSConnection object at 0x7f5448927a50>: Failed to establish a new connection: [Errno 101] Network is unreachable'))
### 执行结果
- **登录状态**: 登录失败
- **签到结果**: 

---
## 执行统计
- **结束时间**: 2025-07-20 22:01:24
- **运行时长**: 816.58 秒

✅ **所有账户处理完成！**
