# 天翼云盘签到记录

[![签到状态](https://github.com/shaoxiax/189pan/actions/workflows/main.yml/badge.svg)](https://github.com/shaoxiax/189pan/actions/workflows/main.yml) [![项目主页](https://img.shields.io/badge/GitHub-项目主页-blue?logo=github)](https://github.com/shaoxiax/189pan)

**最后更新:** 2025-10-31 18:40:43 CST

## 快速导航

- 🔄 [查看Action运行记录](https://github.com/shaoxiax/189pan/actions)
- 📋 [查看最新运行](https://github.com/shaoxiax/189pan/actions/runs/18970083778)
- 🏠 [返回项目主页](https://github.com/shaoxiax/189pan)
- ⚙️ [手动触发签到](https://github.com/shaoxiax/189pan/actions/workflows/main.yml)

## 签到详情

# 天翼云盘自动签到抽奖程序

## 执行概览
- **启动时间**: 2025-10-31 18:40:43
- **账户数量**: 3 个

## 账户1
登录过程出错: HTTPSConnectionPool(host='open.e.189.cn', port=443): Max retries exceeded with url: /api/logbox/oauth2/autoLogin.do?appId=cloud&version=v1.1&clientType=20010&format=redirect&paras=C2DBBAAB61126ED8D6D620AE092FA8D503EDF78168201014F0D318E894F933B7E9E3555A43E8990EA71F1A0D9B1AF2E2FC3F8F5C2C4F5B185A895DC5D6568D3803C837831F27031A8FF2E37E8ECBAD7D50026326F6B389C4ABECEF472312BC8254B5F7495E4F5846718B98EC1900B924FAF6E6067B500A593E2C246AF692FCBABE35A38736D81170505C4499AD1FEB68A1AE62C58BC690F40D85266318CE41BB7FFE836E672AF85B09C7297E49A8696FA067F57F23DEED093ECB7A628C5A726447B65C48818AD1CFB58C0086F7697B26EBDFEF5313152ECF11A920DE8293DA95C68FE54CD005AE03C9A5FD6896AD0BEB7240B1C2F9D27CF7B6D8271D9F80920CE4C7CE544EC79BC9210F1C08B08ABAE94A82FFC79A7094638891FA2EF1793F385E33E686AF5AC0EFE0B6184F9AF92ADAB0EFB33EDECC05E91FE2749EAB4448B1E5C41121098CAB23AB2CC354097AF913C16F7A25776A2D792D042499EBA6EB0ACB3CAEAF7EC139BABE959E6FAF039C9803AB1D82BA3511C0F03144752B406F7C052A98D2A8CA8065C869D877A5283CBBBA59AF3259BC322925E41DF4D62062A0D070EE89ADBE048CF3B4FD5D7D02EE2A88FA2DA67858B02AA7C33739E5DF9CB6BAC6664EC5F8149283FA4E0AC8FD90D2AF3FDC1D1F0CAC5F2C5983565A79E5FAB51E13ED9A5E37BC57A44E7FA12E2D7ECB881885ECD0B47A6BE6DEB6B173C7F4041FEC8ADDCEE66184F006A2F773B6F00C6C8017B3F77C8C&sign=745CD0A86D0C15546C0C70712D593D8881C72892 (Caused by NewConnectionError('<urllib3.connection.HTTPSConnection object at 0x7f40fec8cf10>: Failed to establish a new connection: [Errno 101] Network is unreachable'))
### 执行结果
- **登录状态**: 登录失败
- **签到结果**: 

## 账户2
登录过程出错: HTTPSConnectionPool(host='open.e.189.cn', port=443): Max retries exceeded with url: /api/logbox/oauth2/autoLogin.do?appId=cloud&version=v1.1&clientType=20010&format=redirect&paras=271A219BBB5F1EA0E6F4BE294CE76D302535B059D05D3003DDB531104D5DF11DBEEF95E83F076440DA7DBC54D8B136260CBE2F8546C581501257AEB9E7F5CAFE3154160AB241C760C708092B71396DBC52D37C3E1D59D8A53508B727D6D274F1C73C3B4EDB008D2DDCB04B786B987C8B00A4BCFF65A9DC703BEF946E4201D64391983DB49A5BF953277CA819A3089CAAF7C0B112F4A0094EDA2BB543E410C56F7A2098D07918FF65E2F9487C284323DB246B54585E4380D4FA517EF1A1BC2520D76C25CDDF3E9D97E34E0BD35505786E06C65CBD82F8BA86F8D5FF4E37C0355DBB4B8CF8CFDBD505FCF2638DD46E3DE1EAC3BF0F75DC82EC885F76D6B38AC393C4C2E07C28FA75809FCA34416E1271241943995E7E9266C3DEA29B66B96B8138BAA6F32079BDD5328B8D10A8194554070708AFCBB36D8CB791B61D3B33B8892286451C10E57D37C9790BB5D688FE8EED9287D7FD1D1E77033BA57284BF48DA47F529820EAB509BD2C3A7756501D969DF54314177900B48A79B0DAA67B56CB38D3939973FD2FBCB48DF5A2967E65018A0AD2A3E46184D2A716AFD21D1AE92C49DA4020F9CA5C8A6921B78267428C12AC3A776C37E3440BBE3ECF13CC75122AA7AD81E5BEE5699A3CD7A7F016A3C54F2011922EA646645F8EC073660F77018B44C662D847409CF8346B4A14FB892C11021ED73FCD63F507574AD489D624CDDBC4BD77BB62FFC8963D479B1CC5BC0C3391D39703B572BFED892&sign=B6DCFADB52A72D6B151B4791D217CDA70DFB4E12 (Caused by NewConnectionError('<urllib3.connection.HTTPSConnection object at 0x7f40fec9c710>: Failed to establish a new connection: [Errno 101] Network is unreachable'))
### 执行结果
- **登录状态**: 登录失败
- **签到结果**: 

## 账户3
登录过程出错: HTTPSConnectionPool(host='open.e.189.cn', port=443): Max retries exceeded with url: /api/logbox/oauth2/autoLogin.do?appId=cloud&version=v1.1&clientType=20010&format=redirect&paras=B056A5677D55C0138222D175CB96BE7DA981888C1528E836412FAB48EAFA63F850D2BCB6C5C0BE045842FF863920487CDC2DCA8341E29BD62ECAAEEC54149DB299F007320BC53B75E15EC2154B38C68C7F5499A6209887FBF131FBBBA87279BA85670ABCDD9EAF6A9D74E55EAE0AC171C98814974EC0515626620F20C34863C29CB71C09BA6A7C769EDFC676D0115AF769AC53AFE0EE01CBC5AC65F01E06BE6A90BADC18885EAE619DF78D81BCEE0BD6D5A7B109BF823CC06F27A5171F1617E1CFE39C3CD47E9025557FFABA97632E68B920BD3E979830667686272AE6E38057F51D84D546E58EC28E0301171ADD31236C2474284AE2E3B72751486A567DC83F218EEA645358D35BD2249A97A471C45F2DF26573667D3305165B0205310C9947114DFCDD96B4EC5CCD319F5C1975567F02ACFEE5F67DD98404E377BC6B8A476E137D4216B799C051A6483D5FDABD901E97666AE733A0F5C47ED66DE08387094E1042B23627A2FAB1F8BBB489A2FC43B7593ACF966358ECC28D9ADF38888BB6FB2C8C6F50DB93B1375CF62CDDE1849CDE3D97C13971DC076CCFEE2521845934D2F1814CA5384938F8AA86331DADF2044E8E481AAB3991B188739AB4CE8F751ADEF3328FCAFA12F188A811B6650EA8C3DEE84E18B0927E5E42F6CD0528A9EE46E16FDD75DA3582F366F0A6150DAE9A67C0729D1EA28D4ABBF31945F6C344A14254DADA325D3FC6FB21E1AB03911F478E8F26AC81AD8007A838&sign=D423F1B33CB3E5FBF69A7945354A73F5EE72EFE0 (Caused by NewConnectionError('<urllib3.connection.HTTPSConnection object at 0x7f40fec8f8d0>: Failed to establish a new connection: [Errno 101] Network is unreachable'))
### 执行结果
- **登录状态**: 登录失败
- **签到结果**: 

---
## 执行统计
- **结束时间**: 2025-10-31 18:54:18
- **运行时长**: 815.44 秒

✅ **所有账户处理完成！**
