# 天翼云盘签到记录

[![签到状态](https://github.com/shaoxiax/189pan/actions/workflows/main.yml/badge.svg)](https://github.com/shaoxiax/189pan/actions/workflows/main.yml) [![项目主页](https://img.shields.io/badge/GitHub-项目主页-blue?logo=github)](https://github.com/shaoxiax/189pan)

**最后更新:** 2025-07-27 21:45:03 CST

## 快速导航

- 🔄 [查看Action运行记录](https://github.com/shaoxiax/189pan/actions)
- 📋 [查看最新运行](https://github.com/shaoxiax/189pan/actions/runs/16551791091)
- 🏠 [返回项目主页](https://github.com/shaoxiax/189pan)
- ⚙️ [手动触发签到](https://github.com/shaoxiax/189pan/actions/workflows/main.yml)

## 签到详情

# 天翼云盘自动签到抽奖程序

## 执行概览
- **启动时间**: 2025-07-27 21:45:03
- **账户数量**: 3 个

## 账户1
登录过程出错: HTTPSConnectionPool(host='open.e.189.cn', port=443): Max retries exceeded with url: /api/logbox/oauth2/autoLogin.do?appId=cloud&version=v1.1&clientType=20010&format=redirect&paras=C74DF3F760BF13E993774F3B93EBDA90B0F12E2E53F5AD19873CF2DF705AF4CE823924458F52C0357F8897D7F180432A2A60FE30B3B0E03D41D004B68C4A4950BC6CE14AEB28C558E2DE2DD8421B510E50769753E0B767384D2B0372B5E2D2D8D728156629C1053D4789460017E83CFE51136CDC264D0BDB70FCD997EE4A3ACAA3CB2F4F0F7A69975F67FCA5CFA010073081BB598FE522D2A3040FE73133E2C6386022FF0B036BF4FCFFCBE146EE422263B3558A3F380B73C14E720FA9F37C76CB436A408F5A2FE3D8488EF15F39BCFD7A2DEED52F0A5FD5FD1913E018F13BBFCB3E55365183660FE45D78CB971D863A006BDD31FE3CB20A709BD9F1A6249EE629518EBD220FB3FA4DCBE9E52E316E78DA1487E475580BDEA6FCF7D20FED2AC400D2C638095C5E142FF54E4E4B278FE5C568B99F924CA5FD565D69F0E7B933086BB25D2AE9533C8C026D89D38F97CEB671D744CD0C6977D0F9CB40AEEB8166AEB30033B5A81370F89C80C0E7A083C5AB3A757C30B4877AB5798B4BF508B39E7CB7EA54DE1AE325D7D71522A5F0AC7B585CFA145ED6D2D7C0CF9B7FEAF720A4926DD2B715756A2510B923D3CF85853CA676E304E8457F7A042F04606C7FC81E3B1B0EBE2AB7199E49BE074CE4EB58A6E3C7FD3BCA962F0060B593406A31B5FE38863F72BC841FC0C196BBC8348838254B3F53CC39DCB35711059E3137F8B526304B4B5D130376293C87DFEFB3D59BDC6A3A28AA342C7E66DC&sign=2A2936ABCED38D51A9AAB97137C94E87D777F165 (Caused by NewConnectionError('<urllib3.connection.HTTPSConnection object at 0x7ffbde1e8850>: Failed to establish a new connection: [Errno 101] Network is unreachable'))
### 执行结果
- **登录状态**: 登录失败
- **签到结果**: 

## 账户2
登录过程出错: HTTPSConnectionPool(host='open.e.189.cn', port=443): Max retries exceeded with url: /api/logbox/oauth2/autoLogin.do?appId=cloud&version=v1.1&clientType=20010&format=redirect&paras=565D0032B6A5B04FA5998592776A9D17207098F6A5A6A7A7EC508B130C67BE81EFA9203C874563BEEF1F105CC85EA0AB41AE288BB6300AA73EDBA40BE2646FFDDBB022CFE58B215D9F800D6E289FA8F8B6F08C7BEC25ED705E275B849B5F45993772A231ABEA2190E15848BF240D16A17B774801A506DD4359AB4013D2FE37DD26316B07437C28A7340075D651F3054668584C1F15CE0E979E40AC94D18DC8457399005D87EF9DBA5854ABCCBD553016ADAD8D808A07E13F3ACDF5DEFF0F5C1BC01364B849A07C1B82951885E98F8172A91F9243C4B199B1176150EB9E58099F586B1FF2954354B3FE4E320820DE6E229AE8F3F4346EE6E994DC8068DD41FF9D1E7746507524DF42E38A5EB34599D99C1CBC6E92FD1AA8BF74F541A3BE006854F3673ADB603305C199E328D385F1BF27BDDD915F4199CC2A2D47D04A58D99140D121835A9CB9902B2633232BBC6F954EA5CC9F736CCB38E27EDD2E229AD4F24880A96FE2000AF609D050AEAE5B9FE707D572272C2ADFB2E96A583236EE2108FC21991597C20A4D7A80C5BD461606CFB120548E1A15A38DBC068A69A3D5DD7FF4C3875A45F64492F20027E3546BBBA619F600E287467134C47EE013BD9BEA3F9B8485FAAC89CA651279F3344F4DD4D53A7C4911D9F9BDCCF681BFA3DD309DA4F12D914999A2EFD5CEF48C0F3B636798796C736AB45AD265EE3EE40EF27CB8028354EFB2C803637E997009A465682202F3EFA6EE2B0CC6E5CD&sign=7FE9F70A5557A3F0C4C7AC932961C6AA61DC8179 (Caused by NewConnectionError('<urllib3.connection.HTTPSConnection object at 0x7ffbde1ebfd0>: Failed to establish a new connection: [Errno 101] Network is unreachable'))
### 执行结果
- **登录状态**: 登录失败
- **签到结果**: 

## 账户3
登录过程出错: HTTPSConnectionPool(host='open.e.189.cn', port=443): Max retries exceeded with url: /api/logbox/oauth2/autoLogin.do?appId=cloud&version=v1.1&clientType=20010&format=redirect&paras=7CA3AB25E6482049A2BD13B111B59398D09C0873635F6825B8FECCB19C13FB6583BCA61C16995E7DBEE72ADEB4B65F9ED849FE0111366DE66F3B998B32015DADE4B88F3FD78B451A9560D53D7DA9A99C0B8CE1538435871E8B41AEB0011FBA461FD728672E357716FDDE7CBC4E3580F82CE9C4E8908831242212D75527CF42CBAE880B4DFCCEDB2ACB003D66794949DD0289150369BD275D630556ACB179FA19A1F021716F36A62CA2CA2FDC6EFB4EBAE0EC0AD0638DA3A586FE8D599DB14EFCE6FCC1CAA6129930CAB51B40CF13AA9B4D819BD76C62E98154954354B0143EB6340B562537ABA418A3F136FD6763FA064DEA20903263A3597A2FD743D63E362E96CB0A66B1D0E734811361774D2F9CE67560547A0AA78F93D015C77D9C4D2C5E153164EBF8F2ECFB1C0860BE8A8F24108B5D3EE8A2330F740AF7A59C23277E1A4DC762371DAEDA3AFD6E896906F8A3DE8E78EBE4DA642412D7B77C3293E71123198EFF9A089B58EB2AF244FF204E0ADABDF62DC86C53C0E6A52D5121507DB676D4C494CFB2D3DF1B654D8E9ABED12A05B0088A5CD6C3F8AB37D1D81239ADB3225A1860F80FB0C7EC82F24DAEC635B6FDB3B2827F52CF6ACB5EDFE0D08C7FA275053E4BFCA1EE356D45DD595C3E91B86DE7EFF976961272A053ED3A5977FA01E5B74D86E81216EF862344640C5C731644EF5464BFB29D401B5D3B1D3B71833E4566634AA0DA564D458FAAE66F4442CFC84E19631406ED6917&sign=0562F849AE43795FB21C61D8F04E0A9A4F008F5E (Caused by NewConnectionError('<urllib3.connection.HTTPSConnection object at 0x7ffbde1d7ed0>: Failed to establish a new connection: [Errno 101] Network is unreachable'))
### 执行结果
- **登录状态**: 登录失败
- **签到结果**: 

---
## 执行统计
- **结束时间**: 2025-07-27 21:58:44
- **运行时长**: 821.04 秒

✅ **所有账户处理完成！**
