# 天翼云盘签到记录

[![签到状态](https://github.com/shaoxiax/189pan/actions/workflows/main.yml/badge.svg)](https://github.com/shaoxiax/189pan/actions/workflows/main.yml) [![项目主页](https://img.shields.io/badge/GitHub-项目主页-blue?logo=github)](https://github.com/shaoxiax/189pan)

**最后更新:** 2025-08-15 18:42:43 CST

## 快速导航

- 🔄 [查看Action运行记录](https://github.com/shaoxiax/189pan/actions)
- 📋 [查看最新运行](https://github.com/shaoxiax/189pan/actions/runs/16988367309)
- 🏠 [返回项目主页](https://github.com/shaoxiax/189pan)
- ⚙️ [手动触发签到](https://github.com/shaoxiax/189pan/actions/workflows/main.yml)

## 签到详情

# 天翼云盘自动签到抽奖程序

## 执行概览
- **启动时间**: 2025-08-15 18:42:43
- **账户数量**: 3 个

## 账户1
登录过程出错: HTTPSConnectionPool(host='open.e.189.cn', port=443): Max retries exceeded with url: /api/logbox/oauth2/autoLogin.do?appId=cloud&version=v1.1&clientType=20010&format=redirect&paras=5E6E6A222F480735C40E8B0BAF9A7454D5ABC4C9EC123E2F30F9BDF27698C770B2A8347634D3E649344CDA81438A1BED239AD64F5DEE2B680622F6AA6BC3B289749A021E76B30906A6B73DDCC5988E9AD57E7D21F40AAAB9A9ED90C5147DD7280CB18CFDED88557DD14AE502166378915F8C7BE6AE342D9978A118CA7C74A098B47599E643A0E730D2DB982DDCDBF721D45C380D93F9E0FEEDE150968A5C971AACA0B754397FC4E46998F5F1CC03C019FF6E968E7125D19EACD9CCC99C0067BBDDBDD71178DBBA9A7A0AD997B263A307DD66EED3036750A583E33C992B636547AEE1C5FEBD720B3FE3A78122FE5C9386437BFBAB82E5F83C94742BCAD039A771AE321EB2226989467E1322C9FE5FCDD4497989B30C29FADB6602BC5FDCE0C43B6B3D305E0845FE74344BFB28B226E151131E973E3A84D86ECF9F3959CCCB8889C8A3FD8FFA41FC9E44F7BA0EF6D5AF1CF12ADB00EFD0526CFF40A6219B642C9FF0D09E18CA4D3A34E4DBAB7271269EB521919D6E5E0E77DDC124EE0916C1A67BE88EB77B172CEF09007FF991C300DDA2B18E0B942A3F815DB16B118E8856827A59311DEC639A7E8FE890B5610E42E3AE7F82A8E5777F8337D32526DD5747348414B659C5608BB1D26F1E902BD8DA931C6C542ED44454BFC3BA39A5CAB6356B3A2D963F32AAA4E5A6F023455E3EDFEE4126145FBF2FDFCA1341BAA92A00721BF36A72624571F24EBF4724224461B462520E45513C25356767&sign=122E912C1CFE979910F472EE3061D17A07DA3C1F (Caused by NewConnectionError('<urllib3.connection.HTTPSConnection object at 0x7fd5eb3008d0>: Failed to establish a new connection: [Errno 101] Network is unreachable'))
### 执行结果
- **登录状态**: 登录失败
- **签到结果**: 

## 账户2
登录过程出错: HTTPSConnectionPool(host='open.e.189.cn', port=443): Max retries exceeded with url: /api/logbox/oauth2/autoLogin.do?appId=cloud&version=v1.1&clientType=20010&format=redirect&paras=E12656D81858B7DFBB191627EB34007816483F52448C39880E0D96FA9AA05DB1B6703F7F8D76514133D47954F77A12548B886A1F8AB620F69A50211BEBC435CE52647BA66CF8759F8B2FC885AAEA59BDDA2F455FDA73DB908A4A1EEE4FB865B55C46036F1DB1B95F02A368FD7EC88D86DBF2EA35DDCB0DF9A9EDE08A405602C7C14C5CAAFF71197B92D6A3EC3420919A88E68D90244AF85710F330B55CB9C390B74D9BAD24BE96FB00DBFFDB31B4A99352CBE51D8EC4590FA2EB5B40E3B652846F1F0680286EF622F4AC688713BAAA0ABA09C4D64606C7FFBE26BA1611E5FDDF7FA6599116BEB87C5A219089EA7D015EE93E427D4664F8140272059D9DA0AD964D5D653901DE999F944C5E38DAC1C4A31CB2A55DFB516F25C6F1771BCF5D3292F56E2F995BFE44E73CD8506D842AD1E1E942A569FDF046310E82B8B575033522AC79367476294C8664BF38BE6622C9AAAC3EF803343DFC9D68977405BA52239C8AEFA5DBFACCAF9114E6D86BD940FE7624E0210A1E2A6E376BF1462F694860B9939CE5752159A20EC5C531EC30B198223A4DF068B543A496B217194AC016F0644A351F2F24A6D325C695718F04D0BF0FB432CD57D2C59A0DD9264E92708619CD188347931D9F769FD30699FC75384F03369740131FD8F0C6FF4DC5DE5BD0B80934A93BF2BF8F457E5207D67A6BE280DB20D1BDE27C587F54F7F39A5010DCDFF5FB434393431C6BF1661B5FCA80394F546E15C86F62B775AA&sign=58D717A88D3008E5FD8F374A958573C54BB9C615 (Caused by NewConnectionError('<urllib3.connection.HTTPSConnection object at 0x7fd5eb3080d0>: Failed to establish a new connection: [Errno 101] Network is unreachable'))
### 执行结果
- **登录状态**: 登录失败
- **签到结果**: 

## 账户3
登录过程出错: HTTPSConnectionPool(host='open.e.189.cn', port=443): Max retries exceeded with url: /api/logbox/oauth2/autoLogin.do?appId=cloud&version=v1.1&clientType=20010&format=redirect&paras=E644578D83EA8C01E586B7A3166BE3EB3AAFDA69C98C3750BDCE6480495631E804D44AC3B86B1EA000AB521AA49F230905CA95DB01F1977C9A7681AE82F4129F289AAB58213C2646A6A4E3913FE4584B922A4005F9A7A951873CAFE7BBE5B4E2840511219F57CF422452CDF4FB367C7C625F1C25AB911249D6FAD5583427D1F8711F91083B8AB3171EFC9D69534C0E96E6FC9492B1E9B65F06FA53B28254A92BAAE2154A2B44646C75E694D0374B4E1E6E2861EB2AC7E842A58C77BB07FDC9F314FDD6E1CB2302B89E7FE04CCB73DB392174E1C95DCF0ECAD11E137E02DEA93DBB0D91CA24623A807CB7E8D58702570636BB1008BB6D3D1A338002A71AAD7E8987071EC76E2F6DBC0A7D76D46EC8434230A93DDF0E57EB76CAFE419078C419A4EDBE3AEE7540578B9FFEF4FC4175EEBCA51470B7488CC01E51FAF33AD160941E2107A5091242010B1BE115CEE94966950A77CF3E5292FB254830A984613978D014827747E9BA2B978E67E48D4CFA4FBF1A9BCDE4B4C0A0D8967AD7B457D0FBCCC3ABA3775D7DFA00160C823E9C78074FE69364D749D3A512423608D5B97EB8DA1E3170C0D23FB71982C3B261F104D05B26B29079D3FC76DC120D22104CB54C6A0F953EA0DC96A0C2A66AFB1DAC6A48A1F3F02056CC5E5A4A7F76BB20F6B665CE2F544D44703311E5DCDB0C4D9273A51B704B19336301E990890B4F7C4C1E847D43EDE84E835042D980A455DF82F23B20B1968BA3895BF121&sign=2039AE80F32F0BA1F4E667F13AD1C68AA9B1FB05 (Caused by NewConnectionError('<urllib3.connection.HTTPSConnection object at 0x7fd5eb2f3c90>: Failed to establish a new connection: [Errno 101] Network is unreachable'))
### 执行结果
- **登录状态**: 登录失败
- **签到结果**: 

---
## 执行统计
- **结束时间**: 2025-08-15 18:56:14
- **运行时长**: 811.26 秒

✅ **所有账户处理完成！**
