# 天翼云盘签到记录

[![签到状态](https://github.com/shaoxiax/189pan/actions/workflows/main.yml/badge.svg)](https://github.com/shaoxiax/189pan/actions/workflows/main.yml) [![项目主页](https://img.shields.io/badge/GitHub-项目主页-blue?logo=github)](https://github.com/shaoxiax/189pan)

**最后更新:** 2025-09-06 21:32:11 CST

## 快速导航

- 🔄 [查看Action运行记录](https://github.com/shaoxiax/189pan/actions)
- 📋 [查看最新运行](https://github.com/shaoxiax/189pan/actions/runs/17515154883)
- 🏠 [返回项目主页](https://github.com/shaoxiax/189pan)
- ⚙️ [手动触发签到](https://github.com/shaoxiax/189pan/actions/workflows/main.yml)

## 签到详情

# 天翼云盘自动签到抽奖程序

## 执行概览
- **启动时间**: 2025-09-06 21:32:11
- **账户数量**: 3 个

## 账户1
登录过程出错: HTTPSConnectionPool(host='open.e.189.cn', port=443): Max retries exceeded with url: /api/logbox/oauth2/autoLogin.do?appId=cloud&version=v1.1&clientType=20010&format=redirect&paras=4E6EEC8C309B5918D62225635E694B5CAF5BD153743DF165C9C91D338A2ED1672862A40B1FB482B93AC5822FF135A969CA32C780CC30C4B58B34BEAB477FC42FFB959FDC5360BFE83B4B5DB0B043E398B40D52DD3760D4E9B2EA579FC63416DEAA67EEC6C81607BA880610B6F37FE4BF49D158F183A00FE70249E8F144BF934AC824A9D64185B6C55A180CA19008E2154712D66E3076C08D471A3262CBCD85CD18ADA13C75804D07E275D5C870F0CDFF8FCC7C61E82C1437C4C3F49B4677029B0A37C60B723D1C078A0719A3C9A8A29E77A2B41CCD0F97DABB00CE7C41F5040654A7D541916E7A82F0EEF9E1EDBE56FD8713C055BBD26807D17425BFB46A1C551C798E06BDB9DDAC3474DEC6823392B8FC4941F8E7BE66B145695BC813D94684B805680F2FC7654112ED5EA86A799A6AADF24A775026FEA0568A25682689999F087962F1F07BEF4292543707FAF144889B9C055F5DEACE815A1A2696C1878F4422905FC0E1EAD60539264E5F2DCF40D73ED460719A9F5C4C4E98589A5DC15F13A093225A9C6A420FE4545A5C278D450D86395C4E03F9D81F07E9288D83D8C61DEE93122B0E7686F1D1F472E50F6720B1D36AB37693DCE3B00C44CB84668A2D1F1A1FACF1282BF05E77DD657CDFCE2383EC5633FF84DA62B700C0C205EBF78AEB40F59BAD9DE44FED5EAA7ABC838DBDB55CDF4B817A57FA040A77FDF9F8FF20C8F72284037097FC8104E56AF3A02300DC37950EEEDBFD859D&sign=F76BA6FDF07418AE13B8BE6B02279DC002508FB7 (Caused by NewConnectionError('<urllib3.connection.HTTPSConnection object at 0x7f76bf5c49d0>: Failed to establish a new connection: [Errno 101] Network is unreachable'))
### 执行结果
- **登录状态**: 登录失败
- **签到结果**: 

## 账户2
登录过程出错: HTTPSConnectionPool(host='open.e.189.cn', port=443): Max retries exceeded with url: /api/logbox/oauth2/autoLogin.do?appId=cloud&version=v1.1&clientType=20010&format=redirect&paras=C265A409348CDE76B73BA6AEA752C5FB3C3C2F40D6E722EAA753D1BF50878A8AAC12F43CAE1BF12347F32D1EDB1248D427DCE58DC6F170175C9080B879B4087E5BD44D5BF8E33D737D8C11231DEBA107060B4255B46613E6F8E4B9813CE0237669C2BA230CB1D76CBA442D24B0D88E34856FDCC01CCEAB78259B30402D80B05428AC81F71BC99AE48B32FFC6CD8A51AE40CFA30715563930D64DD26B74CE099A1D4B37289D9B94C868850AE20B2108B5C772784449E8DE807B9F28B957AB15AD9ACB2C1B2A20BC2E63F808965FBE913FB41B676A05EEA6E5D8430486236C91786478F9980E649005C202B67B3623A98CA39185E021310F2AE037AB9910796994016E5AC7037234732535DF4A61F1FE14B8C47FD0DA65A53FFA7AD6A452AC1456BF3848024E8BCA42BDF27F006479CE089190CA3DE39051668B9EB806D1F646B9006DA97884B02015B97364335255E42CDB2A1F85EF9D3E618A68247B2734CC1CAFA975B853A192D83E06EA587B64B74115DFE0862CEB6BE1FC77B91DB447E051F0DD3022DDB1BAF95CF1E68E6FD2DE5F2657307C1E4E8DEBDE2ECC29B6C2972C7BC3C90B19AE621C8DC63AC3801612A6F8812BAED95026CA101355361A18A502FD9D15E5E00AC353403AEF85CEF308DF0C40DFA20B6D9F58AE31BF20C6C9086AE01DC5DC2E3C9083BD9C5DA758AF6AB97DF94412B9FFFC84348B3173F8B867E996C50909B721364CA2715CBCADE5F8BAC3F12B542FB105C4&sign=CE50362AB89551B12420584DA68C613C2365791E (Caused by NewConnectionError('<urllib3.connection.HTTPSConnection object at 0x7f76bf5cc1d0>: Failed to establish a new connection: [Errno 101] Network is unreachable'))
### 执行结果
- **登录状态**: 登录失败
- **签到结果**: 

## 账户3
登录过程出错: HTTPSConnectionPool(host='open.e.189.cn', port=443): Max retries exceeded with url: /api/logbox/oauth2/autoLogin.do?appId=cloud&version=v1.1&clientType=20010&format=redirect&paras=C268C9C693DF84FE001A6A4EF3CE62B4B18433019747BA26E60685F106A9EAF1B5E58BF00B198B3C0BB4BA58F870922C8A880F2CBB004CD66F465BC6377CB2C754087886B1BF92844BCFE307E9402F3C7765DBA02FA9BFF69EC398096F106873435F67815221F14F1E92317668DB30EB64E1A729551FE5BA4F968A774F6A313FE349FEFE470458E20E532FB4B33200E8DBAEB2629180EF7FB9BE4F95B0343194937BD90F0EB0B74A75F165999CD551324682421CC74B8247808B401737D6F8A0CAFD36C6313B10A884BD3071DA8E4ADE4E0D0444A4AD7DF144B4002A3265620F180B11ED7E4E975C0E0551B2D6FABD544B76AF4245015B41ABF08406A9A6EB8CBD1D456DBE8ABD80A76548E2B7AD2F3513A306FDE969BBE8DED5D9D01694B049353FB3C248704F27BB085CC0D207F06A5C4D2879AA24107A50012978E3C4EA3CD9100E1953B09BB12E5AC57CDEDD064F6CE44C7323A01BCB5D9473080144C2E839243F89E0CBE9F1FC2378493268E409AB44E7BC2F5422246CD447876E51526BD76388B836EA6DEDFCD113E655ADFB518D697717F687AF2065657589D2483343EDD5E3101E811EF32637ECA5FD3F854550C6F98EA31BCAA3680BCD1B2292767DFC7CCBE9B595E182C7F9676BB9E01BB2111DE77FFA31179ABB43F1999436E38DBEEDA1E3CC101311BFDFF9FA8C973799B49AD958B1697DB75801408EF06BD32D5CC881589CB0168294F511F6A799481B23C110F3A4DD4DCC&sign=3DF3B1336351B54B15E01F91A6CA3D75A4D10731 (Caused by NewConnectionError('<urllib3.connection.HTTPSConnection object at 0x7f76bf5b7710>: Failed to establish a new connection: [Errno 101] Network is unreachable'))
### 执行结果
- **登录状态**: 登录失败
- **签到结果**: 

---
## 执行统计
- **结束时间**: 2025-09-06 21:45:51
- **运行时长**: 820.62 秒

✅ **所有账户处理完成！**
