# 天翼云盘签到记录

[![签到状态](https://github.com/shaoxiax/189pan/actions/workflows/main.yml/badge.svg)](https://github.com/shaoxiax/189pan/actions/workflows/main.yml) [![项目主页](https://img.shields.io/badge/GitHub-项目主页-blue?logo=github)](https://github.com/shaoxiax/189pan)

**最后更新:** 2025-09-19 21:41:07 CST

## 快速导航

- 🔄 [查看Action运行记录](https://github.com/shaoxiax/189pan/actions)
- 📋 [查看最新运行](https://github.com/shaoxiax/189pan/actions/runs/17860040830)
- 🏠 [返回项目主页](https://github.com/shaoxiax/189pan)
- ⚙️ [手动触发签到](https://github.com/shaoxiax/189pan/actions/workflows/main.yml)

## 签到详情

# 天翼云盘自动签到抽奖程序

## 执行概览
- **启动时间**: 2025-09-19 21:41:07
- **账户数量**: 3 个

## 账户1
登录过程出错: HTTPSConnectionPool(host='open.e.189.cn', port=443): Max retries exceeded with url: /api/logbox/oauth2/autoLogin.do?appId=cloud&version=v1.1&clientType=20010&format=redirect&paras=C993A6790E54F491EB01C028238938CC3A6BEBA7EDCC2E92B352B730E3F9E98980B6FD7D06350DDB56A0F955ABEC9D98E26DB22ED00A89DD8AC8A873F5AB76C8F0A326A13F5A061A9069DE12D160120C1431EA7DF47882C98D3F96B8F0139FDB85903C00D6C99D99FC1B415F86A61044B50C32979E8DB7E2A6C99BB800065C20A1DF3A6C07B58A89F1CF7BC2AC8253931C20FBF80D822E7E9798802C2F077B8A1322DEC593B5FBD9D0482982F3CBB572A464419C54E72C807B60F850CF4A860900DF446672CA72C69E23D80C0B5E543DF7D790DE990697A6BE2C4D765C0D50918ECF4ABBD4432655ABED3578EF7FDBFF86B74C4543B54F4EC5F1D55F3E1D495E792C47F5EB6A64D10577EC58758C0CFB9578EF4B320339C42B1C8C80EDE740A2D243E74EF7C08701976A9779EC5A13FD0D6BFCD399137CFC92C4B6B1F61DE559C0A7CFE2D770AB1FC29516EA18CD1F14C052D62D5EA37C0B7713D8C87AA9670444A317CD9E3E7E8955BAFB245BEDF57887028C936D0ED66D038710B751298AA178557F1A53D3FB7E2324A8FFA7F35EF1582499FA8313531048A6A6142A0F52B838A521A933D3640C5CC03664A3CE9D565259695318F19CBE37CCCD3809F4395B0A2B582DE8C20A9FB45DD86284EA40B3FFE58903EBEF4672AD2178B3D5820482A70397D07095D501C7734A3AE1E54158F37E149C90C8D3387C101096F76BCA32E7CFF8586A9BDFFABD9FD3AF617FAB40AAC206908E5ABAF0&sign=8BA7FAAC77B4175BBD8F68A57460AC59A89A41BB (Caused by NewConnectionError('<urllib3.connection.HTTPSConnection object at 0x7fbe47f0ca10>: Failed to establish a new connection: [Errno 101] Network is unreachable'))
### 执行结果
- **登录状态**: 登录失败
- **签到结果**: 

## 账户2
登录过程出错: HTTPSConnectionPool(host='open.e.189.cn', port=443): Max retries exceeded with url: /api/logbox/oauth2/autoLogin.do?appId=cloud&version=v1.1&clientType=20010&format=redirect&paras=7835B2B01198C5594106B92CE20AA7B65C6A74085DC6212F148A7067D4FF56FD1F6CAE5D75404045ED32A8312F0AC6942C9CB2FCEA97EDE42670973BECF576A2FA9096078E7C395A6861738DA77355F6E3A8BFC1B7085BED34B130DD02C512ABAB9F64C68F5D0BD238A0655FB8D2D31D412D31C4550A4E30F1E27B4F43121C6DA00D21200E68D0B5ECC5E53F6037654EEEDC1C24EAE2C238813702E31834421E1A94A8E064FB82E5C718EF8EE15EB701342BBD91D5E56FE975E02DC362EE1A6B1F730171D0D0450B39DA0B96A3C0A84E0D3118ADCCFF6DA596FA54CF11F3B6AC3470BDD2C0E65CDF9B8590ED3AF6A238DD39843B22609430FE7E035EB14310E32B63369CC4CCF384715888B49F289DB26ABFC0996C7DDF97640410605159260344DE6866C86D4923A472AD3D9F2638E62A6EB79A7EAD158E86D88B9FFF0BC88B9532BAD881C91A98946F8C09E5370EC67A304D8EF71E9531FF92AC1910167151FE84816502D6FD6C8D774747250CAD00487B3500BAB6091863C92447C1AB84436EB22F45020F56BC7C116402396145334696A8DF10562E8FAA85730B95EA5BFD66952DB4B1465A2351F7023AEF2BBD2FC26C854707FD243CFBC0F01073D66957AB611CA345FA471C01D037EAEDB63F89E4D2CC9FF9FD2C1E86A0C0EB5B1CCC81BF8DCCABBA54532F078BE3A840DDC274F0DCB8983EE15CA706FAD89B924529FF68651E1B72705251498C26520FF316FA89212D4C4517790F&sign=A46DB83C3F720913DBEC941A7E95C256A86A30EC (Caused by NewConnectionError('<urllib3.connection.HTTPSConnection object at 0x7fbe47f14210>: Failed to establish a new connection: [Errno 101] Network is unreachable'))
### 执行结果
- **登录状态**: 登录失败
- **签到结果**: 

## 账户3
登录过程出错: HTTPSConnectionPool(host='open.e.189.cn', port=443): Max retries exceeded with url: /api/logbox/oauth2/autoLogin.do?appId=cloud&version=v1.1&clientType=20010&format=redirect&paras=3A805852ABFE5CF96C6BB3864AEBD519110429BF77DE07ADBB9AD242DFD2550E01CD3F4F6D04B6C8152D6E790BD583D34756269399AFEA2670F703ABF96429CA8851ED109C1436D687B7AD74B98D4B8476FF82660F8E571402F0BDD4A5007E2E533388A66093E03484AD262BB6E807BEA5FF687EFF3134225A93622F145996035E80BC0ADE40BD28407B11CE127CDCBA3957BE53FC412E15F41A962BE02F5B6B2A041520D10C45E75CA7C434F702904350E20BB219AF50284C2027DE3AEFF49E72B06C269C53CD6A5645C949F653DA59119E3756E138C9D5B5B311A5DC301E60617A7E614720E5881DA725832E8D36815F4AD1C15229F6F3C788FC9BF5FD606AE2B740700636658D373C3A1C1EE2E296ED9C605274276F1AEBF494F6C5F61CC63EF13B7F86FB4DC2B9C24DDAADFEFAE89C4109E29562C73D2C4CABAA86077781EB4A73B9B103AB9F857F51E584DCB9677E7C4657159E7199106DD91FA93AEF6BEFD28FFA188987891F2E89D405CEEA2CD8E89C0C1A5E96B69004DC88ACDDBEA613839A6A1410B56B531D8E1EF9C55D154F4587A9844E61D355149F53A04E5E158536B8D40F12F1688243DE85E030D10A400A75897E00FE5969AFCB6732D0E9FB8C1779E5C207185BC0514BB8466BE109DB0EA5AE084A8C56D5EFFF49ED0F3EBD1B8DA2B07A6FEC8AB5DFD6BFEE5F01BCF705F8B564790FCACB6562C058F9F7F67694967E5206F1A17B4D8A445BD5A8EED8E6220B444058DE&sign=4F439D136766AB230ED983476526C0480EE26965 (Caused by NewConnectionError('<urllib3.connection.HTTPSConnection object at 0x7fbe47eff6d0>: Failed to establish a new connection: [Errno 101] Network is unreachable'))
### 执行结果
- **登录状态**: 登录失败
- **签到结果**: 

---
## 执行统计
- **结束时间**: 2025-09-19 21:54:44
- **运行时长**: 816.81 秒

✅ **所有账户处理完成！**
