# 天翼云盘签到记录

[![签到状态](https://github.com/shaoxiax/189pan/actions/workflows/main.yml/badge.svg)](https://github.com/shaoxiax/189pan/actions/workflows/main.yml) [![项目主页](https://img.shields.io/badge/GitHub-项目主页-blue?logo=github)](https://github.com/shaoxiax/189pan)

**最后更新:** 2025-10-30 18:41:42 CST

## 快速导航

- 🔄 [查看Action运行记录](https://github.com/shaoxiax/189pan/actions)
- 📋 [查看最新运行](https://github.com/shaoxiax/189pan/actions/runs/18937913459)
- 🏠 [返回项目主页](https://github.com/shaoxiax/189pan)
- ⚙️ [手动触发签到](https://github.com/shaoxiax/189pan/actions/workflows/main.yml)

## 签到详情

# 天翼云盘自动签到抽奖程序

## 执行概览
- **启动时间**: 2025-10-30 18:41:43
- **账户数量**: 3 个

## 账户1
登录过程出错: HTTPSConnectionPool(host='open.e.189.cn', port=443): Max retries exceeded with url: /api/logbox/oauth2/autoLogin.do?appId=cloud&version=v1.1&clientType=20010&format=redirect&paras=F777AEE8BEDDED4CAE694675F98C1BD7AED3D2996A77AC3C21938FAB30D14C2E413DB1D473492DD72988CEB235EE4497DCBBB0704F2C3B23139DE998EA3BEE63E4D279FA38D2A4A0B01ACB7C6EE7F24DCAD113AEBBEA58760E918DC376A322D74DB7738E77A3A314ED123F94257DDB39A1949D347E4FFAC8DEE5E4A6DB1BFD5797BE336AB31989AD8FE4040D0280AA49EAF6D52A7AD484C7B494B7E25B4EC34DE01CE7E6432DE3ECAC2FB280C37390FA46E5E48C54CA47E55CBD07D2A32E896B1226644C28B70285E6FD8064BAA6B784D4165344C7D2757E479BF582091DA32A82DF9009AE1B29D2737DF5264FEF5FB3718255F2AC549FCCE9B5AAB9C4B2885D26B0BD0858F85349E1C0739281F883C2CEB9256C21835071F1E3F78179FB3AD3935543162CB3FB49943B2E0301BDC84B93358FBC90244EF0594BDF8895DB2C3FB1F46D4A60367EBD589466DACFC20FCB640ACC6721749D348B3F83DE279C0A7EBF4A77D94519E7E7A533E09F9BEB2B54D242147ECC7A862B815CB27FFE6D86FD4706B7E42F82C94C49F71492AF6724064043F7DB11BBAC5E57C356669E6E92D29D3A849E1BB94C914A718D54ED95DD015672391CD72B6619E26106714DFDE6C45D8681AFE84F8A9089A1AE5D19052EBC45FE30DE9E170B58EA4F543E19C1E824E725FD739964780D7C6E82DBF73723010C4437AC074AE8DDE55143E5141DA2C2D98B0D8180F33424694A1D9CB8AD231894D7D5BDC9781D85&sign=6C5F27CA1EE0E7D4C99821ED506395DDE24EE9CB (Caused by NewConnectionError('<urllib3.connection.HTTPSConnection object at 0x7f1bab144cd0>: Failed to establish a new connection: [Errno 101] Network is unreachable'))
### 执行结果
- **登录状态**: 登录失败
- **签到结果**: 

## 账户2
登录过程出错: HTTPSConnectionPool(host='open.e.189.cn', port=443): Max retries exceeded with url: /api/logbox/oauth2/autoLogin.do?appId=cloud&version=v1.1&clientType=20010&format=redirect&paras=7DDF9138373C47C0D49A29080BE858B5BC58FEBA26E0A92BC62A415C4FC594C8F19EEC3BFC29C8513AF178C4D962D653701DC658E0B5BDB0968C65AF3DEDBE04D31E760BEFADE8B47B287CF253CC805517DF59721043414BABE03CA2ADC67A1788C6CB53771F0B55B1BAF363EC8EE68F00DBD2232DBCC6B4D3A33121DD17E3B2FA40206F1E575543ADD47613CEAD91DCB65DBEE18CF3A5C453DE9BD1EE197D36D449789A1B1E003F365B1329253CCF9F4ACBECEE9A9EF088822177032DDF8427DECF45188327C07AD4DDBCAD53AD2292040A909CF8C147DEFF5754FAF9F205E9C59B87CAD2C5F123EB889A418A53B9ADE25CBEB6B0A56A586BDCB452BA6B0986F39A115DF52F5EBDA348174820AB4CA0C432A923921B31392708FAD45BF5F842FCDA867DA0B21239F437EE7221A7843B52E34D16CF6045368E3DF92D29DAEF0754A4BC07E5E00925B8B1928C1A40D2BEB5DA1E58BD22F53F9493DAB3245E2A972DCC732D1471A148C0C046279F25B6AF0673F961FAC37DF899AB1188AA8820B02E12F8B60FBDE025C5607A7CB89B3779C92A3672A89B2F0A79744E4590B66376DE02D019F12B519001E67290E5F6C5FD7C554F7E6EB532DC73002B860069ADD296E409AE9DB6FEB4365582962EFE9C103119DD9E5ADF0ECC3CE988CE10C9A9A439776A95FF5A75EB042B2E9410FC2F4B7D960A23315088E0F87D1E223E315F898BBD82C8F5F718CB41AF263A504374857DA27250E103773B&sign=0F616B8E89CF7E04725A94459A4918674BAE5C4F (Caused by NewConnectionError('<urllib3.connection.HTTPSConnection object at 0x7f1bab14c4d0>: Failed to establish a new connection: [Errno 101] Network is unreachable'))
### 执行结果
- **登录状态**: 登录失败
- **签到结果**: 

## 账户3
登录过程出错: HTTPSConnectionPool(host='open.e.189.cn', port=443): Max retries exceeded with url: /api/logbox/oauth2/autoLogin.do?appId=cloud&version=v1.1&clientType=20010&format=redirect&paras=4D98CD1ED9C7908138AD4DAC290EC2C33EAFD6EF3619A40389EA625413D13FF15A207EAEC316476865353DA1215E09F8D55950553C7AB22612FBFC624DE814D7A9FAF024C5ECEB588AEC644CC6D009F9231FB246C775132D6DEC23B23D528F2CCD2F981301C36BCB561E9040F238D747C2EF10622FA7D1B882CE094043F13D9B86A0DEBA87D17C06645D2DC29FC591E83E8122A801FC1B2314F83051E589FEDD4F23AC0AA23341E183EF32CCDEE7960B5655D645058854D655E308139E29332BC604B4142665BC7DC0661AB6B7908650AE771B8A39028D724D26E1F3ECEDB996326C5C9F4DEC36452CFA741B123E71D62CCB3686FC1744C2666CBA3306DD8B78C2D726E686E4E3F838C3EF099AC7622EB6ADC585B4CBD4AC8C0D7539DE52BB09E7E3BEAFCA97D4CB0D648C0C82D594F6CDC6860960F6A6A2DBD8759E91C660C40E398F82D586B544F2A90070CCEDD98C6219C3F747CB763AE71225610BED3BA3F0DB06834B0E20636A7E44A0710EC08E288F061166D9F7FF350131331BDB5AAE72A1A914B381B1CB9E146E57B2481EBCDF12B8E8B64D4EEC29860CED0A12862B53ADD4488F80DC8CE28E01B69A960DEC4F98AF547507D8878407B1F906EA7F4F17AD435251E6B2C080A462F8690FD815F1792D89068D7BB88400CDDCE81AA0A7236391A0E9E2837F0A0989EA3186A8123FF55F99083D9C44951AF598D123F33947B8ECFC48973FCEDDF61ECFF3C7E29394DD7046894E6800&sign=C038B8A7521050FE78CA6112BDC6D40BC8E5C6ED (Caused by NewConnectionError('<urllib3.connection.HTTPSConnection object at 0x7f1bab132650>: Failed to establish a new connection: [Errno 101] Network is unreachable'))
### 执行结果
- **登录状态**: 登录失败
- **签到结果**: 

---
## 执行统计
- **结束时间**: 2025-10-30 18:55:17
- **运行时长**: 814.17 秒

✅ **所有账户处理完成！**
