# 天翼云盘签到记录

[![签到状态](https://github.com/shaoxiax/189pan/actions/workflows/main.yml/badge.svg)](https://github.com/shaoxiax/189pan/actions/workflows/main.yml) [![项目主页](https://img.shields.io/badge/GitHub-项目主页-blue?logo=github)](https://github.com/shaoxiax/189pan)

**最后更新:** 2025-08-01 21:52:26 CST

## 快速导航

- 🔄 [查看Action运行记录](https://github.com/shaoxiax/189pan/actions)
- 📋 [查看最新运行](https://github.com/shaoxiax/189pan/actions/runs/16676845624)
- 🏠 [返回项目主页](https://github.com/shaoxiax/189pan)
- ⚙️ [手动触发签到](https://github.com/shaoxiax/189pan/actions/workflows/main.yml)

## 签到详情

# 天翼云盘自动签到抽奖程序

## 执行概览
- **启动时间**: 2025-08-01 21:52:26
- **账户数量**: 3 个

## 账户1
登录过程出错: HTTPSConnectionPool(host='open.e.189.cn', port=443): Max retries exceeded with url: /api/logbox/oauth2/autoLogin.do?appId=cloud&version=v1.1&clientType=20010&format=redirect&paras=DE30E7EF4FB4409068218761818A2094C63A2894C7CEEE09F22714BEA7EE33E1AE2ACA73D697629B0B86F193215270C9232AB611C94AA32A3360A28C4EDD393B52BDE16650EEDFBE2A6BA20C98BFAC063C5037A090E15CC6E4CB2136D46E7FC18E908F73CF23DF2D4E6342D2A7FC8995348597E02BBB76E6B3C5ECA2BB21171269CB7C8068C498150D3F21B990C92EC64CFD26E064DC3DE56E42C51D6482227B57015E9205C66D69FAFE51EF1609E5974077A2D9A474C903D85EFC4E9676E1849C363809792F11EBD357025FD75769D48CE668D7DEC87D0F35EBB298CA2912E2F4BD042DCA634140EA8B064DC99324C5652236CECB716616A1FCA2CA2B5E0B69746A441D9323A80543C527760165DFC11F601DAE78831A775E58CCD44095A05F29BB2F927F24FA6F05B833A876BD0C06C0B7F064BBE3308DB3B46CD8E6EB34981883777316DB57695C15AA96E65C0771C7E513E6AC67B3FC1D6252B15C4163B240552C6AC0FB827A6235C6EF5D471CF4D31370A59C0E46C0A7327B3A30EF38B0FF1AD2D6DE9B6A2A2FFDC7019863AC09822FE604881DCA36F07AC2802E77EE8D0029B5E2AC032DE68CCC81168EBBDEE14B1BDBCF1D8388C466CAE0B308666D55479DF895325CB10421AC5A7E29236BBAB35B839B3F690A269043A7B9BDA5188E2BF00799EC726C5F1F74BA33534526863C66C47F890EEE16B9EB89595BBBA1B3ECCA0EAA312E38547AAB47E82943FCD02EF0FE7BE781F98F&sign=3B2B0D1ABBCE5598109CA4E54876D314CB23CC1B (Caused by NewConnectionError('<urllib3.connection.HTTPSConnection object at 0x7fc732ca8710>: Failed to establish a new connection: [Errno 101] Network is unreachable'))
### 执行结果
- **登录状态**: 登录失败
- **签到结果**: 

## 账户2
登录过程出错: HTTPSConnectionPool(host='open.e.189.cn', port=443): Max retries exceeded with url: /api/logbox/oauth2/autoLogin.do?appId=cloud&version=v1.1&clientType=20010&format=redirect&paras=CA2F7BA162AFD88758A0F7BB9DCAFEDFAF56FF366418E3ACFD5A6750706F54283FDECCFBDEEDD838C83AF5DB3CB5E6822230000AA97EC95C1FD57C582F32775B0B8323BDC7A7788EDF2B6AB86001F6FBF0D7E23A25EE4A9F6482A91CE8C61850968B42EADD9AEDB1BD40B2C2A58C8F9C590CBA0DD900909C1E06A820A003CE7810A067DB156BD5EF8CA92FFC7EC9C27FDD99D9F8ACD4149E692371483F44284FF8C5BFA7EB87A37B1361E273D5225670B96AC7D3FE48495882025226FD43626686E7ED35597D1DE8E62A93D5359A4A18CF4ED5254A9F1108E11FD9CFD2AC5C17235D89C225D3C4E02E12D8C2124E7C851FF2210BE90DB592B5AA6A5FCC074CD1E05ED3CF7CFCBA5FFFC48EE21F8920DAE208A40E9C01D6221CABFAA053065B59C3D11E3130035E9AA24BBFCB44B32779962C5E7CC50EF6F7B05B57368615AF1BB50D5EB71BC0857910CD4FC85ED81507C96D5CFE4561B7B541B7C9A9E37C6D77EC959A511F946DFB1D44A3B260E5EB9A56E65344EECCC1B7A4CD3DE05A64563042068B4BC69D0667CD279DDE429FCA68064CE01E1D66DC4CA1D43EB54E235A46963DD89D8D6A28A861ADC7CE18D62CD4638E49954C51D0283346FFD956C9A52435878298B30C988F19DF5A16DB3E34F548FF5B60BAECB76B2965D52E3B39014285EA0C5D87F7354F377F1E0E4AA82B2E4F37BAD9F1C8DE84BF5713DD2D6E17DEA1258F739719065341527FDB9005952A687DBF955E6BAAF1&sign=F1D3CFD92E609B2D5CBCEEF1ACB3C1CD1727EC32 (Caused by NewConnectionError('<urllib3.connection.HTTPSConnection object at 0x7fc732cabf10>: Failed to establish a new connection: [Errno 101] Network is unreachable'))
### 执行结果
- **登录状态**: 登录失败
- **签到结果**: 

## 账户3
登录过程出错: HTTPSConnectionPool(host='open.e.189.cn', port=443): Max retries exceeded with url: /api/logbox/oauth2/autoLogin.do?appId=cloud&version=v1.1&clientType=20010&format=redirect&paras=C7417F6610D7612AAEF1D18CBCC85050B1F623DB111C38490ADB13E10062EF12D8A768C426CFD65A581C038F444F2D18BEA5E51E082839AA39DA04C5F2B5D83E28883FAF6870491523FF28AFD17D410DCF29871BC3E704FD58F3C32763536A53EB920F775E09278C87CA2E2BC68C973393353829A71F63FB2C4F8E11CACC14CD54537314291AB24296F7B3B657A10A932F61642D638084EAE866651029973679D3A58094F272F927C68B67C37F1B393AF91BED08EE0EFEB4EEBA19DE91B532CEFACDEB837A61A375DE8586A2AC00AE861C768C749FDE2FC23D4DED7586BF87EDD3EF7C82031C1E24E16B7408E557BF840BA4DDE3DA93431FB6CBDD9760BC681FB4F25280BA04BE5C239E3332FC62A3094BB9FE468AD407B1E6F76F594379271EFD0203215B48F602FC762BDD78BA80F6359E4F828676A6FF9D1590D6CB1BF73831D552F3705C3BEFC66B2AF7CA69A025DDDA974454EF80AC0E43502E7E94ACA92970DF348D8D0488F380882840E15D30745360F3631BD0BDC0F5C059BDC4035D87E4430C3F32D1672DBFA180382E02769B25B9DD8F9B8368F648FF1263F8563C25843C706F5BD8F70D89DC685CA7225ECC470723E6AE88C3F9F66975CD2CC365E37C3413574BD727E74BF507253E1A0D8C413B614184BEDB4A5BD4E78C8087A6DBEA60B0CE87E9D114243F043E6E8A3E0D7D43CB1E6D6448ECC21EF828411E565B5D5EFC205BDA3B3F4A3744999EE5B3D3337C283E626E46&sign=21A47B8F3DD4C554EF9BD81BF3F97556761BEDDC (Caused by NewConnectionError('<urllib3.connection.HTTPSConnection object at 0x7fc732c9be90>: Failed to establish a new connection: [Errno 101] Network is unreachable'))
### 执行结果
- **登录状态**: 登录失败
- **签到结果**: 

---
## 执行统计
- **结束时间**: 2025-08-01 22:06:04
- **运行时长**: 817.85 秒

✅ **所有账户处理完成！**
