# 天翼云盘签到记录

[![签到状态](https://github.com/shaoxiax/189pan/actions/workflows/main.yml/badge.svg)](https://github.com/shaoxiax/189pan/actions/workflows/main.yml) [![项目主页](https://img.shields.io/badge/GitHub-项目主页-blue?logo=github)](https://github.com/shaoxiax/189pan)

**最后更新:** 2025-10-27 21:46:31 CST

## 快速导航

- 🔄 [查看Action运行记录](https://github.com/shaoxiax/189pan/actions)
- 📋 [查看最新运行](https://github.com/shaoxiax/189pan/actions/runs/18843173825)
- 🏠 [返回项目主页](https://github.com/shaoxiax/189pan)
- ⚙️ [手动触发签到](https://github.com/shaoxiax/189pan/actions/workflows/main.yml)

## 签到详情

# 天翼云盘自动签到抽奖程序

## 执行概览
- **启动时间**: 2025-10-27 21:46:31
- **账户数量**: 3 个

## 账户1
登录过程出错: HTTPSConnectionPool(host='open.e.189.cn', port=443): Max retries exceeded with url: /api/logbox/oauth2/autoLogin.do?appId=cloud&version=v1.1&clientType=20010&format=redirect&paras=D9F51B634FD99FAA1355D717F0E37AFDF1A239EAEBAE2BAB360DA30213F35A04C1558E591BDBFAD6F57BB9129213181A6DB0AB7A5BFAA5E0CD78CE7A983E28878983E452F6197CC3B9840472008D70CE0B73D432FAE0385A4F72F71DBDCF8226B852B49B5EFAB6ABFCF63AF22982A69C7AA4FA2F1F1D9620DB48CE0FB73979475508621769200B59EEC4DBC8EDEF6DD7FB30F5553A942BD05138015EBD6FB03ACBB1C16E07F96899970354875E24A144E5D44160AFE9F013A51C76C872C886ED7AFE78FE6D62E986C75BA308841D9BFE5D2DFF69E46344F50D83A134F5D3EB529B63C192B99335ECA6AC39DA5C32E41AC0DA20C3AFB4C0AE0B7AED1F8F3A395FFB600A8A48741A0061AEA5435CE84F483D3ED4EF956D5D3C7ADEA1CD7513593CA785B6C1239CC20594A42B1E265BECC0C9FD053C4B7904CCB28EBF0816315FE38C6F0EF8286F23E9C4024A04BC5C90C2EAF0C98CA546BA98FBD31D941EE904093829EA49C024F22AD54474C712A3A56F1C11A99EDB6CE04C8B9847181E23F1FA51947F1291F5715CF7F7DEF85521E571E1ED8626BD34FEC547535107DF2CD2EA1841D6A224F3890B3292B46D570DA341E8E0436B062AE461881245CDFF651842EE490E28E934F128DEA04D0C65177AF53FD105570329B06D84F7F5E3FE6E54BC0A8FCB8C4C654E7401988CE321EC44B12844D35ECB3CC6A56EF6F0582BD05CB3C7EA58393190FFF1B5CDF1C2436FD6C7882AE8AB45BCDB4D&sign=57AC8B1868F80EF799DD5F99284937D048C776E6 (Caused by NewConnectionError('<urllib3.connection.HTTPSConnection object at 0x7f5307fb0a10>: Failed to establish a new connection: [Errno 101] Network is unreachable'))
### 执行结果
- **登录状态**: 登录失败
- **签到结果**: 

## 账户2
登录过程出错: HTTPSConnectionPool(host='open.e.189.cn', port=443): Max retries exceeded with url: /api/logbox/oauth2/autoLogin.do?appId=cloud&version=v1.1&clientType=20010&format=redirect&paras=01024CDC37653B91BF2C35B63E24084CC1AB7715F5A9824F7C172EF48A648109DD7A93D795388C41D9DE584F4CF4DF111B0AF72698AF4E66716A1E91A16536DDDD2F632630679E171159B5C2BE593EA86840793969BFF26F6151D52B0065D2225A2D287DF130E12E73788978F3E0BF57591B8B56A62EFB221EE3F462E6DF4E0442851840898613DE999AE5F589ABB81DD201414A0F34D53FED39AAA4D85B1B7B0A1103FEE0DD1BB8D77C20A8EDEB35E0465843B2457B17C2F07E889C0F51DB987C3B47699EA2F9C0C3657F5E13026B861FEE0EC646B7428BCA907EB79FE0BBB951B408AD25E33F44581B471B0F73FABC12E94F8E304AF5A46549402AE711BE33B7F54782042F69BA27D7AC2CC36A887881D8AB7952C6E23A339E997FA02F5E1482E9CF1388FE6A66BC60839A427EF13C8B2FF603A2802B7BE435E0846CD4372E45E1DC3DBECEF5D7F8BB3FAD3E72127C37E62C0ACDA309ADF7EB754874B1F4578DBADA6CBD9A92ECE20B9F31AF37CC7B42B0564A4891C3004AB2367300E6131424DE020F2058D40FD4033C39E9E59E078A3EC3235A7E15B40A2A9AC9DFA8065D3B624B2A9D7E8B681080CBAE4E1B4838A4CD54E9A3DA2A1B4BC62F86724E175A0D4AEE72C77E1781CA453E218CC5D3810EE6F3A0339D8588C7E0C2A4940764F7780B7A2BBCD89EEB47183D7750F3B76D90ABCA09FBCC2FB67C371ACC194B36168926220F92D8D23FB7A53AA8985792C02CBC0586F19131BC&sign=C13F71F61CC68AB03AA815628B1720D65E310423 (Caused by NewConnectionError('<urllib3.connection.HTTPSConnection object at 0x7f5307fb81d0>: Failed to establish a new connection: [Errno 101] Network is unreachable'))
### 执行结果
- **登录状态**: 登录失败
- **签到结果**: 

## 账户3
登录过程出错: HTTPSConnectionPool(host='open.e.189.cn', port=443): Max retries exceeded with url: /api/logbox/oauth2/autoLogin.do?appId=cloud&version=v1.1&clientType=20010&format=redirect&paras=BD8FB47B80348B23E2228ABCB6AF9F970B1E535A3B790F7CC4C2E868A7DD0F7DB37A04685DD010B3BEF19B6705F67F16486B4DD32483DA6B57DB3EF4C58BFCD6AF8DD948CB772B4EA743BD8C48103C4A8C981233F2B00ABDFB34003128DBD2FA17DC05A9C838BF73DD5A826CC7CB162455AC8D502C2C8702983CEA4722CE2A7FE00BA8A56B471E5E127498D9031693C74EBEB7627707CEA51A641D0B084122B63D852E8F48F82B46F04566C29F19E70CC391C1DCAF8D479E4DF6E254A6AA999537A05689E4A4E0BC0483E0DD84C2F4B7D7D8A05B0ED9081AC3D6761852444766E5CEFB23F58363675B540DBE81193BD72478FA230308BA8CAEDD742E006560A8E8BC68CE64AFF48C304EB22CEBE82D2AA93800FD13B6381B15371046A7572B4FEB54EE4CF6D8D6CF0E98D336B8470F845EEC4BE259371BB4E814AA026A8F1FAD8A042959255BF12BC5A496CB3AA1665DED0A09374860BB75A960329F61A2208C4989EB14C2F4A3BAF490B14ED91EEBBB56BA6445FE12A16775D64E813EB219EFE1ACFF6E8BCF06665D7334F608CF8753C5424A5264861A5DF4C0F424B34A0F9216B868CE950F1B245A590698E66BB1B823F359CF6B18365E1292B31A6FA4F9D63BE80952D7210FE1CF9015AA77C8329197406FC3C8F94E8EB2EA4DE38DC924EFFC9FD932680E1B9717E9D1218FA60B4B7567C3FECB2E8721BEC8C23A9184FE2FD4FA7620042C000CFEA8FA095CE5738B825B1508C155A9F2&sign=FC0495106F390BFDD79A4C137502DD4BE527963D (Caused by NewConnectionError('<urllib3.connection.HTTPSConnection object at 0x7f5307f9f610>: Failed to establish a new connection: [Errno 101] Network is unreachable'))
### 执行结果
- **登录状态**: 登录失败
- **签到结果**: 

---
## 执行统计
- **结束时间**: 2025-10-27 22:00:03
- **运行时长**: 812.68 秒

✅ **所有账户处理完成！**
