# 天翼云盘签到记录

[![签到状态](https://github.com/shaoxiax/189pan/actions/workflows/main.yml/badge.svg)](https://github.com/shaoxiax/189pan/actions/workflows/main.yml) [![项目主页](https://img.shields.io/badge/GitHub-项目主页-blue?logo=github)](https://github.com/shaoxiax/189pan)

**最后更新:** 2025-07-18 21:54:28 CST

## 快速导航

- 🔄 [查看Action运行记录](https://github.com/shaoxiax/189pan/actions)
- 📋 [查看最新运行](https://github.com/shaoxiax/189pan/actions/runs/16372316581)
- 🏠 [返回项目主页](https://github.com/shaoxiax/189pan)
- ⚙️ [手动触发签到](https://github.com/shaoxiax/189pan/actions/workflows/main.yml)

## 签到详情

# 天翼云盘自动签到抽奖程序

## 执行概览
- **启动时间**: 2025-07-18 21:54:28
- **账户数量**: 3 个

## 账户1
登录过程出错: HTTPSConnectionPool(host='open.e.189.cn', port=443): Max retries exceeded with url: /api/logbox/oauth2/autoLogin.do?appId=cloud&version=v1.1&clientType=20010&format=redirect&paras=E27DD1E840AEA5CC5029981DDA9BF3A555BF25CACCC6196D8EE0CF641664FE95A124AAE7D1ABFA3AB2F6CF831D9C5BEC30F7D1401D59C2CA4F951DD24C0F7F82842168842C50C35E74326432692654CAFE308300E6AE4AF0DCC9A9497894CD57FF9FECF4456D53CB9B085C860E312CC8BC417F036E55B1B6D528D01AAB35275FB960338FFC8C523597EB3F9DD532508F03D96EEACD00D3227FF1C2857215B1DCB554D10C2083D2A01157573500833651005F5B09FCDE8288D17DBB09EDE4338D871602AA49441A55EA4B2D4BB2DA31F7A69ADF8E8EC73DD7359A91FAD18919BE451DE799A2B183D7944EB3216B5C0092A5572148499821394D7E19E37DCECB123A58D5138D6F88AD571F6BF1ABD02B3026805B48E6BE4BEBF818B5863C7B4A6716C39467B23F4A59CDE4D4173BD3FD8CD4CA854760FDF8D732527AB161F4D1925664C268BCB3B9BA768A9C114621415D534425F0DE56993F12B8CDBA95112BB9FCC7B28E5A48EA571D35953E10B6BE8C181EA7D703A03DE54C02752A653FC82EB126FE5DB75BAACAE51BF21A420A57C706FF5292FC323276AEF9B3FDD294A211B3230FD879B2DEC7B4DB00DDF1A4787116E64B5AF1A1F87ECFAAD3E616A4422527964B85DDA2A0836BB37BF4ED8AF19C6225D55E9EEF18E5A5A0B78895094AEF2CD0FA33DFC32A8A41EEE41174CFDE4DF5D6B881F852BB15A98C2DC7B1F1695C1EA5154A5D20DD3D4D0054F06F1E310BA402B0348D6CEA2D&sign=B9817008AE9C9D6359BB8F7826F7263D270DA49D (Caused by NewConnectionError('<urllib3.connection.HTTPSConnection object at 0x7fc322b64550>: Failed to establish a new connection: [Errno 101] Network is unreachable'))
### 执行结果
- **登录状态**: 登录失败
- **签到结果**: 

## 账户2
登录过程出错: HTTPSConnectionPool(host='open.e.189.cn', port=443): Max retries exceeded with url: /api/logbox/oauth2/autoLogin.do?appId=cloud&version=v1.1&clientType=20010&format=redirect&paras=142C1D8A7AA8D1537CF77063E355A19F73723D2306B7AF9B2667A8F17D51C4CB306BAFCA7BFE35E4CFB63D4E623B7CDC20C9FF3CD7C85E57D20B35EA2AF26569619B79C732B74891B616928151D9841525888133287CA162D0C1C4FDD0ACDD81A2400831CE544AD3418A7FC0FB69924740A448F33730FBB69AA78283C2845B48B6AB815F046955F9BD9F3B6C7537CA71A0D8598FFD90CA0035648BF0E9359AFEEE9D70FC0A5736C807020F5064E71F3E376CD61B39F633338BCCBC4449E616051AAD7B35F709E07F4889A0A6C81AD9292DF689597F233A9DBB5F8DDF923949E9DDC3F1754CDDB6D35EAB43A2AFBB43FFD5E1C5976240AC70CA3DCFEB9B4BFF24C2EC99DA0995956076ADA6911947B56F29425B3AC5A570C52F27171389EEE067B0B3DD5700064C7535C1758780C2F697B13C58085C2FE860E56E53BC264EB9C5C90F7F7F0BC43A3EC20AED9A6DF9CAB88F78E7F4C1F34FF489E96B3BFE3BD7F4ABFE0C77C91264800281954E84BEC37A5DE97853C6BAC4D70514D991B0B6D5E6FBA7DB6F4012C240D46BEDC064D273B1E030DB5E18E0440F82B975C230FD420AFDB6EBD850181F9D3B905043DDAF9AE82ABC72008308E626E1DD29970553AF9FBEC94F14BA9CACEF9371332A12394295111E7BD217EFA82519F31990B540E228DAA6AF1B9700FEE10D3A0C9DBCF847A4BEA583E932F9234C4927C29AED36A3619F8B3ED61EA1530B1D82463FB1C2275A2854312FC01B9FF4&sign=F82A861B3572A90ED63202074B3418A14A430C54 (Caused by NewConnectionError('<urllib3.connection.HTTPSConnection object at 0x7fc322b67d50>: Failed to establish a new connection: [Errno 101] Network is unreachable'))
### 执行结果
- **登录状态**: 登录失败
- **签到结果**: 

## 账户3
登录过程出错: HTTPSConnectionPool(host='open.e.189.cn', port=443): Max retries exceeded with url: /api/logbox/oauth2/autoLogin.do?appId=cloud&version=v1.1&clientType=20010&format=redirect&paras=E1F2E0853E815B3A84E0CE854FDC1B78D4A25377F5AFB2D61AD41CB7206F44A3B7F1011D25FCB71EC0561670912F4E0D4018E2919D7A5DE4F540A08B0A2E731E067725716D70FFA0DDF5EF5C3365292C26E557A14F677936D73F5879877E8770FF66451F8A9FD584A323993F19D423318A587AF95F13B21238A566ECE6C3CD427F5F313B20882CA9EC549E30C641207E35E972D95B3B2ED30F65490C308528D1304FD0BFCFD721D59A8CA22FB460D0002AB52516485763847A70484F33F42A475410133189AC055C5EE657E52234A6853959E4BFD11DF368A3D78885428B7F175D7E64AF3A464F9CE925D8396E581F2BBD7FD2A339B1ACC3353367B1049FADFC534D60BC4B86B95240EB51750FC4192AD9048121854A53D7E9D712FC9699846D8E84564BCAC3A00674FC64147CE01832EB79882A7CAFD6493D5BD92DF5499C7D8DF2329E1FB0EA0D5CB0579A5CA359385939FA3E90F4166C042F2C276423DD17D5812B34C6F4D68E36759C33792F0CA415D154683E361AF174710F8D905CC717250BEB5A69D6D1EC222FC5292551709242195DAB27ADA5FBD27706A4D4BD17850AFE4368132EB559F483A5CF3556D3B76B7E9214B26EB73E3A672D5CDD954403AD3094C758C92AD5C06D4607A1F4B7660CEBEDAA22E38864C94A8ACAEBB1F038C9EFB9BF62F67A5C8BE49081C9595AA19276F1AB9303365FFBAB7270AEA655CF143E3892A8324FF05BCB0883778CAD73D920705363EC6E7D&sign=9AF3AAFF534B10DEBB661DC5CE44EE9547A2EE5D (Caused by NewConnectionError('<urllib3.connection.HTTPSConnection object at 0x7fc322b5bf90>: Failed to establish a new connection: [Errno 101] Network is unreachable'))
### 执行结果
- **登录状态**: 登录失败
- **签到结果**: 

---
## 执行统计
- **结束时间**: 2025-07-18 22:08:07
- **运行时长**: 819.56 秒

✅ **所有账户处理完成！**
