# 天翼云盘签到记录

[![签到状态](https://github.com/shaoxiax/189pan/actions/workflows/main.yml/badge.svg)](https://github.com/shaoxiax/189pan/actions/workflows/main.yml) [![项目主页](https://img.shields.io/badge/GitHub-项目主页-blue?logo=github)](https://github.com/shaoxiax/189pan)

**最后更新:** 2025-10-21 18:40:44 CST

## 快速导航

- 🔄 [查看Action运行记录](https://github.com/shaoxiax/189pan/actions)
- 📋 [查看最新运行](https://github.com/shaoxiax/189pan/actions/runs/18681182302)
- 🏠 [返回项目主页](https://github.com/shaoxiax/189pan)
- ⚙️ [手动触发签到](https://github.com/shaoxiax/189pan/actions/workflows/main.yml)

## 签到详情

# 天翼云盘自动签到抽奖程序

## 执行概览
- **启动时间**: 2025-10-21 18:40:44
- **账户数量**: 3 个

## 账户1
登录过程出错: HTTPSConnectionPool(host='open.e.189.cn', port=443): Max retries exceeded with url: /api/logbox/oauth2/autoLogin.do?appId=cloud&version=v1.1&clientType=20010&format=redirect&paras=FD90F6E2190600970BABD293DE6637F8FB4E472A0A3B44A40880F2415A039DF1D8BDC4F8EC25C35A9811909C3D889798C340172124BCB263F2222F1644B4C842160153AA41E517DF7B33EACF5E58F231EEBD38031C0132E0221B3D7D1A871B719FA6579E39D4231BF1293DE8B28B4133435E10A0FA61FDA55AF705E0296659787423092F0494012C666A6928B8185D9AEE2D38D2807BFB34E48EE0D8B75F711E1635C34A49F63E55952E6E319E4D91D693743E5BE8984CFB5BCDFC3F9AA51F5736D356B38578C86283BA8DED743B8541845CFB4ECF31DEBBC812986017C155D0FDDBC64C6AFB4FBAE37A46F080541ABD0BF198EC12F929A004880683C604A7E11205C98EB23B883913C0A5DD02163B62D0CC1B5DD086EBD4B69052DBD3D7FD86FCE50243242C7FAF1BA345623AFF75445A1649D8FB74B5DE546161CBA3410E560F96A537FE0F0ED56B5DDA4008584ACEEDDF90622CFA30DDBCB49B504A855F7481AD75E9AC9FA54D03BF2B4D4BF367A7471F3FDEED8F6CB54EF61D703B249BFEC1B5B469190D1AFCAD47454A21D061BCCEA0E109E7775A748AC4230E6ED5728CB594B7BA4E806E59AB61566E78292DD8E991718208A720FD6BA761788F390A8755C49E42DE74A0B1C6B7BB6C2627F83A102229FEFE47F0F20CAEE9B0E3DE697E570C45C8A4C97BBA0550BD310846342A352375BA7FF45C145B09DD1EEEA662B6DB560396EA46E69A97DD8A3CA6DF540DE7D42331FC38AD2A&sign=3E55E5ED5CB8B8B2AA3E5DD34C51BBBF42F7A4CE (Caused by NewConnectionError('<urllib3.connection.HTTPSConnection object at 0x7f01e8b68990>: Failed to establish a new connection: [Errno 101] Network is unreachable'))
### 执行结果
- **登录状态**: 登录失败
- **签到结果**: 

## 账户2
登录过程出错: HTTPSConnectionPool(host='open.e.189.cn', port=443): Max retries exceeded with url: /api/logbox/oauth2/autoLogin.do?appId=cloud&version=v1.1&clientType=20010&format=redirect&paras=898C439C95635F661F3489C17C92FF12BF538DD88E6C23074A00C10C156196FF2702725099C035D0A95ED59BC1FC805D50F28DF1C564EF3E5E891D6A520C5FFA93520A5F79F3FC6820382322743C7FEDF8EAE7D22D3B3FC095CEA47842ADAB4BF9D4F9F55EE2FB5D1958E5C6BDEE58FFB2B139380E224B9EC3CFB50B2B2AF30C4B16286578519D7FB9E53226E30DCD1E9430F59CD694C468F78CCA60379203DCE279EB8A3E6AC4BFC9A7DBAC7DB13B85143EEE49FEF184C97F2547F4AFEAFBE5F930FDBE405DDD5DE477A1B651597F20F1A5A45D6544B9F0D0CC0A61DC1205797B8E7A0007EC48301334AD0AE5C4CDABEE6E2A04A19504D135B2A86AA611EB7AF5854F7BEBE822A92F02BDD1F39A934DA321E63CD2389718609144E8300E89F0FB60B9278E759D742D001E61B649519AC0240FB9679E2F3D6BA0B600A8AFE78C963C74554CCA0F70AEE0727908028632C755A5819EB777F1C4FAF65B40A643E8B7743AA6F370314260D9114401E4001155A3E00E1901169EDD8B587E1D69E074E9D5F38925EA7437019E057E533FE64176693547877A314F7E9AB1EC5F55666286873A1996D2BD5EC66F209316BF5B2515125792537C10D6A92F1DD833E41A01E267A9BA31AE7A9810D4ED9811437DADA3FE9CF3540F391C6E67DE2C1AB9CA5F27E94165375803C13F61BCDCAFEC3ACE3C51F88AC264E388E3E27F03724E6EABCA872AD56A5F292B3C22C8010709F568169817E49C51A1BE&sign=41AC10D7C60C64C03D155615D924427454782790 (Caused by NewConnectionError('<urllib3.connection.HTTPSConnection object at 0x7f01e8b74110>: Failed to establish a new connection: [Errno 101] Network is unreachable'))
### 执行结果
- **登录状态**: 登录失败
- **签到结果**: 

## 账户3
登录过程出错: HTTPSConnectionPool(host='open.e.189.cn', port=443): Max retries exceeded with url: /api/logbox/oauth2/autoLogin.do?appId=cloud&version=v1.1&clientType=20010&format=redirect&paras=877DD04F2A14587FF8F7CA7EE9A5C1972720355A3F6DA162FED04BED3EFBD77299F8F0D519588978F5571E4D6A691FE2A8E8A3F999FACAE34F31BCE96251ACC71E8B4A663C15F4B57770EA312DB2E4E8763F56CD27A460998A954F6F44F7952865B0869DBBAEFB41B476A09FE884ADA4EE3118E1909C350ABF19B7D00753FB106E9EF6978D4880365704CDD6E36DF5172C17D6A9D0DBDB84127DA0E20884C1B85FF08E94D565E8ADBB627EC466B819696401EBECF5B8DB7DB499250E1ADA5379D9AB21CB563EF2C390235BDF97814CCBDC9EAE23A0C893E4CECE1BF697A36BA7FFF7E03F414276D1F909578F98A364FF72E46F33942AC68BF2F7C50EF9226542C8CB3FADDBD80FC9F4ACC348A259BE6C07034CE14DFFCC8C034AF9AFBC12EA128D858217D9A8C81DA5AC5BC3058A7E616F35F42BD217ABACDFEA44BDDAB2666FA7C652D421D32DC9F61BA2661D1E75A770B598619B61ECDA13EA58F012C50F15634A1A424464EDB9F30D4EB33845D5F9730F4597C94424F64123751F8AF1D67F191614C4A3C01EC231DDB3640E23E35B196A4EFBA7B779FEF3D494B96B8C0E25E0C717F8D1D2E5A33F577A588A03F18FC4BA7AA13B0470EFCCE63FC740E95432F97FDF8A732CE37F5A1BC628A18CAED71014B33122FBD1FCF9D140C6C0393AD521BC748B5EE1EE03C1476E9001A0B3F944D9186D65F32786B67279D83D16FD9017A671BC3A5D813800350F0E7D2510BCF203A0856508FAFE&sign=EC9C9BEBB4DC24247366D0ED587750A0F0EE59EE (Caused by NewConnectionError('<urllib3.connection.HTTPSConnection object at 0x7f01e8b3f590>: Failed to establish a new connection: [Errno 101] Network is unreachable'))
### 执行结果
- **登录状态**: 登录失败
- **签到结果**: 

---
## 执行统计
- **结束时间**: 2025-10-21 18:54:15
- **运行时长**: 811.07 秒

✅ **所有账户处理完成！**
