# 天翼云盘签到记录

[![签到状态](https://github.com/shaoxiax/189pan/actions/workflows/main.yml/badge.svg)](https://github.com/shaoxiax/189pan/actions/workflows/main.yml) [![项目主页](https://img.shields.io/badge/GitHub-项目主页-blue?logo=github)](https://github.com/shaoxiax/189pan)

**最后更新:** 2025-07-21 11:21:41 CST

## 快速导航

- 🔄 [查看Action运行记录](https://github.com/shaoxiax/189pan/actions)
- 📋 [查看最新运行](https://github.com/shaoxiax/189pan/actions/runs/16407747780)
- 🏠 [返回项目主页](https://github.com/shaoxiax/189pan)
- ⚙️ [手动触发签到](https://github.com/shaoxiax/189pan/actions/workflows/main.yml)

## 签到详情

# 天翼云盘自动签到抽奖程序

## 执行概览
- **启动时间**: 2025-07-21 11:21:41
- **账户数量**: 3 个

## 账户1
登录过程出错: HTTPSConnectionPool(host='open.e.189.cn', port=443): Max retries exceeded with url: /api/logbox/oauth2/autoLogin.do?appId=cloud&version=v1.1&clientType=20010&format=redirect&paras=354D8671CDDF90F95A313D3439AC93DC03F7C120D4CBAFCC9FA2419CD809AB56189A761FB117FF09417C53CBDCF92700883B715518A2D330BA46BD09ED65F29E976ADF36778374E1F631314AD09092722A8AEED014DD6FD80766241455BB70B6AB04C510C54F20E6C6CBDFCE45A29340CD4EE8658AADC35742229BA27E658546D6F360AACB616BF081C8881A78855D5902F019E717FA2F7D6499D859BC0109CF315F4B56945C1CB1840D1717657EB6ACF5810BD11FC5FBF209D7F4BE97446C1756FF3CEED745AD94ED7C35A442D51847891329662DE7B5F8BBF7126D6E3C17E91C4FBD3CAF0EDDFA28F6291AD22BB3D622DE1F3DE720FC70DC409A9F03C3B9971B2FA19C598128D8FCA65AC1E4ADC9325470076A8EAEFA5A0AC0A5A45BFDE804AB4D1F2FB55AC28DB2F38EBEED7FF88AB6A0DB6ABF5C2CE5A88CD7A542040A1FCF37ADAB97D9DAC302DDEF8F69FE3EC2496B97F32A4A6BD52F8EB8424F1AB1CF5CDE9655A5E4E95A19F0ACF0F0FF0AD6907F8C89830E5B9C786716D25D2546A594E74B9654D507BF9226DB6E9558AFC13DB9D18D79E969DA1E6CB56BDC247442AC1AE6DDC50CD98E6377317D2AB4702B613AE6E5B1F7F519E8AD4F1DE42150DCDBA29B423A198540A179E53F2F6446A00728074E98D1C2657D41208175EA8D45D829219338C778A4E5CA8028B66BBC446B1815141428CF8952D1CDC7C8E85D6EAF3131F9F7B4939864085D652151510C445A9EB0B6E44CF9&sign=6B9E78D23AADFCA51FBBD8AB223C0C1A24D22A84 (Caused by NewConnectionError('<urllib3.connection.HTTPSConnection object at 0x7fdaac8e0950>: Failed to establish a new connection: [Errno 101] Network is unreachable'))
### 执行结果
- **登录状态**: 登录失败
- **签到结果**: 

## 账户2
登录过程出错: HTTPSConnectionPool(host='open.e.189.cn', port=443): Max retries exceeded with url: /api/logbox/oauth2/autoLogin.do?appId=cloud&version=v1.1&clientType=20010&format=redirect&paras=6FDC0EA9A2B5A9394499E335A1F9756533136497E9391EBB6A4EE3DD74F1F78610F5F4E7A2979F6BFD38E57E6679B8B139E25E1D2C23BBBB80D95662F380CC987689C3CD1DD4241F93ED95989DB523A2DCACBC1C0A444065A7009EF740E8C9C7EF5615D002EDE99802F78082475020B10F314861676699DB1F5BF0E5AC1F94378C0581412EF85C97F42E634D6B6BE0CD3A1E55E7AD18911BF5A7DA9D36BB05AA15486BF6AD437E929E0D6C62360F30A71AF1BF80FFD20CB5762BE0812848D69E1E89714BE06AEA631471D4EE78FE3C01B4362FB1851D7346B9CC84E9D0A099BF0401F0DD2DDAC85F3FB3B3305FCE44A9F714E4A5C79F47185407715EFDFBDB0375767C90F5375F61B63B187A05CF8AD0F99B0E068DDAF28F42073B9C62C9A86994E93535025F1EAA6633CAF5ED8F525FD68ED7D8C4D766CD71050B0B8B72EC427EE667AEAD33194F6D7E3E8BD62821B6BD47210EDEC2B334156F32F2ABC1314DCBF61DFA88B2908455558CE8E635C963AFA8B047A77D86B4E0FF92B1E41EB7118D8D740657535B05F388A1D5AAB7C5A45ED0E74092EC941AB6C17E747D51DE94192FDD5AB1548A7198BA29740C19795561278D7F3B8B56736BE85C26D3254092E36EB54C3F6628B43D5097F412A299AA4ECAE4D35146D2B940EAD7057EA80A3B5CD91AA55AD51C3D870A6EF99529ACA2C14010BBBFF1A0F9DADA453245DEF8089E37F6EB705CCE3D4B1B1419775CE765D444F081FD9EBCEA&sign=88B72172C33047A6BE1E8A73AF905CC945737293 (Caused by NewConnectionError('<urllib3.connection.HTTPSConnection object at 0x7fdaac8e8150>: Failed to establish a new connection: [Errno 101] Network is unreachable'))
### 执行结果
- **登录状态**: 登录失败
- **签到结果**: 

## 账户3
登录过程出错: HTTPSConnectionPool(host='open.e.189.cn', port=443): Max retries exceeded with url: /api/logbox/oauth2/autoLogin.do?appId=cloud&version=v1.1&clientType=20010&format=redirect&paras=2951BA6739775882294D43929490853940C3FBBEB92A676C37FF3053B4A1CD6F9166A571C9CF62255555BFDA809488AD3A956B76FCEF345DA848FBC60F3B0017339F22938BE8427D5DE5341D844C51AAB7BCE488C41D6ED602F73A0B743ACC0F91604C68B169FE9545A026E9079834575811E8977A7022E2402AE7ECA20DDB08F5977B0E08EBBE3B8202F47C1C796E174B28FE1B78CB519D41855C5527CA92E426CAA7003D528381AFA6E5C80F5C3ACC7E280BC675D05817EF54736DDE95EEF6DAF2BA2D162DF3BADD36FF07F42FFBC203376D9B635212EE8DF16A8535A854329137AD6D14F6BF642BA385CD1EB664F9B0B87038FDF3404AACF9097ACAD884519BE7A81FA5F4E62E68E3894D673DEEC3E0BC3F34F634398340D05311E3FF93525CB86CF3B34B62DD8F842B926FDDFF13347BC94D424594016B024712C14095123F840F5D88EF901E2FF834E9E1F12F7FDF3B808EA4143442551665ED33B413A42D9C49ECC0158A52E30651C15B6EE3F481E4DA1CB2CC6D4F02471BB97C9B8B080A3C2EA02393B7B46F2BA483CEB9D6B729F8679154B23E0DDC2F4323C367EDE3BDCA6E2A1843C128BC4A900EE4363391C67EE45E946DA331342A8748CAFF042A52A0F036C5DEE32829E898219B467576CC22E229F58DCD231A4FE967E5B17F115203B921F3019417EAFED33A25C66E0B3C39A4A7D78E9D8CC26020149F78DF6A4470D237E4C5A08E7D243669309C7F60620636513B8E65CA&sign=3B85C08CBDBF18E8F9E5939E4B160B93D2E0035D (Caused by NewConnectionError('<urllib3.connection.HTTPSConnection object at 0x7fdaac8e3d10>: Failed to establish a new connection: [Errno 101] Network is unreachable'))
### 执行结果
- **登录状态**: 登录失败
- **签到结果**: 

---
## 执行统计
- **结束时间**: 2025-07-21 11:35:14
- **运行时长**: 813.09 秒

✅ **所有账户处理完成！**
