# 天翼云盘签到记录

[![签到状态](https://github.com/shaoxiax/189pan/actions/workflows/main.yml/badge.svg)](https://github.com/shaoxiax/189pan/actions/workflows/main.yml) [![项目主页](https://img.shields.io/badge/GitHub-项目主页-blue?logo=github)](https://github.com/shaoxiax/189pan)

**最后更新:** 2025-07-25 21:50:39 CST

## 快速导航

- 🔄 [查看Action运行记录](https://github.com/shaoxiax/189pan/actions)
- 📋 [查看最新运行](https://github.com/shaoxiax/189pan/actions/runs/16523609451)
- 🏠 [返回项目主页](https://github.com/shaoxiax/189pan)
- ⚙️ [手动触发签到](https://github.com/shaoxiax/189pan/actions/workflows/main.yml)

## 签到详情

# 天翼云盘自动签到抽奖程序

## 执行概览
- **启动时间**: 2025-07-25 21:50:39
- **账户数量**: 3 个

## 账户1
登录过程出错: HTTPSConnectionPool(host='open.e.189.cn', port=443): Max retries exceeded with url: /api/logbox/oauth2/autoLogin.do?appId=cloud&version=v1.1&clientType=20010&format=redirect&paras=FAACA4EF540549A5E7DF2C1C26068917694C4F5B2E6874F95A46C570D869308DD47D53225AA8AB85D6A2BF1A52CC13E1F71E88935469E977367001F3079B4BE9D42B07C54B2DC6225A5A0443509976088FA8E2E4013ECF830092B41D0BD805AE253FCD4121B77333E6F28D5E8DA27F1B4B1CDD266440173CC98FE000D1E4E4EAD0613D2B30AA1DC632D62E3C460D4FA72D890147CC903E364E566CCA46BB46DC30BF9FEF65390BC644408170615D24FC7E8F4AE75FA33A59E1C588343987B5C84F5B87DA9BA685AA01FB9BDC932B5CA8825314D2966408CDCCC38295ADC4FD40AF9A5B74BD021FF03CDF0F629BA93C9C794FCB48CE4B79DC4CECA1A8CAEACF538493D12030A276A599FF625CA8AEF4990C762DE6E60E6AC3DB693C80C28A5B9B5ECBB0B022E46B07470E3541F6060C9EDEB162E7C2A260F6F3BD7EAE6E3FB6507B6E0CFC676DB8C2B919E8D2E5064681D614A4D418B8EAB7E03C43D620F0EBD875FFA6A705D53A417091E5880A41B1A995964FC388A3C5968E3664AAD82B741DFBE7FAE360507DD84BC197A7AE0D6730E2009CC99DE2ED19FB620F5BEBAF07CB0182EEF924F285F5E216CECB4A6716B93711D2939E94FB61F40F24C03EF25C972A90C21DB813A53C03274429E42F98B16BF902940B03D6311CB37BD049A2C6B3F7F38BC4796039857E395BD82ED53D249E270A646430ED2175EAC568163187372B5637AE00F2AB5B6C00EC21A0B07D58C470830E756538C0&sign=80D421102CFABDFC7234FB047B1821D04BAD6F44 (Caused by NewConnectionError('<urllib3.connection.HTTPSConnection object at 0x7f40b9344690>: Failed to establish a new connection: [Errno 101] Network is unreachable'))
### 执行结果
- **登录状态**: 登录失败
- **签到结果**: 

## 账户2
登录过程出错: HTTPSConnectionPool(host='open.e.189.cn', port=443): Max retries exceeded with url: /api/logbox/oauth2/autoLogin.do?appId=cloud&version=v1.1&clientType=20010&format=redirect&paras=9CB9EACA2D40AA60B0B1A98039FFB00BFAB30308288C0A49B1738AC11B8CBC88936FEF556DE8BFF9AF48947EB6DD67CAC6F68AC8B785B6F238673951823390F857F837C679982464BCA091B7918A5DB9DBC4DEE204D2A87A7F95DCAC36B53E7777C316C0A3564E9B428BDEABDEA82B498222C498702912A81ACCCC8F920B12ED70FFA86E88684079158B91BFAA867E697913CB26918B60E85BE6B5456B3556E91370DEE76F8110897EB7D7EF57DACF623DB47E262F9CCB67641807CDB3ED69B6E948A2F1787AF41763C9F36AE5C009EEE71F230108376AA03CF6A86F00772321EE9B350A147705F2A98338F4CBC87D24C93896C7DE1571EDBA15912DAE42BAA862CC0D6844A09EF925DCD362BE4F0101FD779E0FDF911DCDF007BEB567CB89587731A39D2302D0E268996C1C600C444B0F912A3F2155F323DB82B25A69CC69CF6B2BBB2E46CA8E8C9348C0186465F41378B18D92B577395845280E1F2F263484B4EAA528D4423365FD37A24F61DD49C91F50FDE86E81055C80B698C0A65ECC5A523933C053E6FD641BCBB9372CA5F93CBCA1F11A1221EF37B56AE08ED1788B72362B3C4A7948C29CD6E3850F556A7AC51A62429CD5AEE2CCB835CD81AEF219C1BE3D43B3297E7A8488B0551281B571D3F4BE7241038F88DF5EDA935AF6E1AB71314832465A3EA227199C33FBD46E9147C3C56DB43C70865E546C920D743831EDF68B952E23FBAD9AAB138FC7B7F9BCED031CB050B3CAC438&sign=A62820FAB01BAC78E375F3DD52F213FFC2AE15AD (Caused by NewConnectionError('<urllib3.connection.HTTPSConnection object at 0x7f40b9347e50>: Failed to establish a new connection: [Errno 101] Network is unreachable'))
### 执行结果
- **登录状态**: 登录失败
- **签到结果**: 

## 账户3
登录过程出错: HTTPSConnectionPool(host='open.e.189.cn', port=443): Max retries exceeded with url: /api/logbox/oauth2/autoLogin.do?appId=cloud&version=v1.1&clientType=20010&format=redirect&paras=F75D1B1645CE7771124F7402BFDC4C18550B45169CED0057CB343FD0125AB6F0D63506C86AF7451DF41485E42C74400EA2EE61D7CD826076777047048F37D2B5E7CF3469552949BEEAEB2656EED5CF0E95F7CB3D3BD734F9B9545292651362CBFBBDF20B6A926D46C80918709DC2B17FAA6F62D97444A684D240743039410B12C014C04EEE88D0F0756BD2A207CEFB74BE4B1F87447B521FD83002DE38848F1635C5A9CEFC66A891E41D9F5EB6F105B687D5205D93E096457D755598210F800ABE9547DB1DD4D7E2956125CE89E5F51F815C397115CAB88DF1AB4A1B43D31C395B6164B3B860E103D50E987C5E02F0E7BAD090D087B36D90BD77A9C5DB5D4BCBC1EA16B479DF92D77ADDCDBC93D27089E8A9A5B122EAFCD2A618BAFF3836B21462E5901BAB18BE5DC5672FE8A1C0FE3BE2175ABC52FF02B49E0E7C86083C9BC4FD96D6E74312C4A738B517BC5B1CC97D4A1F231D7929467EC62CC7A544EC2AC209F707F95C1D1774CB25DF5E57FF01919884121480C1B2DA79971C1EFF0A88AFFC710F62CC05980C8E9ADF8D4B9631906CD01828DB6576DDC83093A033F204A04608174DF44D615D0DCE5E05019C1A4FA874F24009C8F4315E98A34A802E9F357D0CDD11A9427B0B5FE0F3C114C5DD29163165CC3E467BEF3293DE87FAC30996244C184EF81A42C7AA80644A844B0640ED5AEC8508A9906CDFF80DFBFCBD9AD7F9C5D3413DB52838106A47C4DD20CC7021A11EBC824FD3B3&sign=569A6F7C4B3DA35FB0CFDB57C30C42AF6018391C (Caused by NewConnectionError('<urllib3.connection.HTTPSConnection object at 0x7f40b9337a50>: Failed to establish a new connection: [Errno 101] Network is unreachable'))
### 执行结果
- **登录状态**: 登录失败
- **签到结果**: 

---
## 执行统计
- **结束时间**: 2025-07-25 22:04:18
- **运行时长**: 818.66 秒

✅ **所有账户处理完成！**
