# 天翼云盘签到记录

[![签到状态](https://github.com/shaoxiax/189pan/actions/workflows/main.yml/badge.svg)](https://github.com/shaoxiax/189pan/actions/workflows/main.yml) [![项目主页](https://img.shields.io/badge/GitHub-项目主页-blue?logo=github)](https://github.com/shaoxiax/189pan)

**最后更新:** 2025-07-24 21:54:52 CST

## 快速导航

- 🔄 [查看Action运行记录](https://github.com/shaoxiax/189pan/actions)
- 📋 [查看最新运行](https://github.com/shaoxiax/189pan/actions/runs/16498858896)
- 🏠 [返回项目主页](https://github.com/shaoxiax/189pan)
- ⚙️ [手动触发签到](https://github.com/shaoxiax/189pan/actions/workflows/main.yml)

## 签到详情

# 天翼云盘自动签到抽奖程序

## 执行概览
- **启动时间**: 2025-07-24 21:54:52
- **账户数量**: 3 个

## 账户1
登录过程出错: HTTPSConnectionPool(host='open.e.189.cn', port=443): Max retries exceeded with url: /api/logbox/oauth2/autoLogin.do?appId=cloud&version=v1.1&clientType=20010&format=redirect&paras=EA2D22C07E45AA366A6F32B7EFF1C41C8CD4BF4CC18F4248E9A1DF333C7360D063B6C10D8FBF976AB9EE8C06E91B5F4B375D946C92C425A2DC2D67163C16FDDE0EE6D7BA72F091252BE633D102B1C3CC9EAAF4623C04BB8077AAFE95C32CE4124F9900E3A067668D3966C2292461F6426BB1E2BE2BCC0D78B8EA7DA5BD4860602239F87E895A697824B888D8AC09776F576A64B756A10E849638F68ADD2D0498A558E570E528872C19981C0082CAD6062CF5369EAC2C3CDA3240F88E910BB06D5633B86FEEF6554C0333E5811B059F05241E9B5814377DB893377804360CE49A96A5505477E9A7758B027D1CD004F254A148C8972BFCFEBC070134349FFE9BA1788711A1657F03D338DB43888C3187E8C9B46FCF6EF56FDA4FE2698EAAEB5A061FE1C6D1F6FE8FD33D24AED0C8C5F6D675675594E5CB190B9E29F6A5506AE69BCBB678A181C68E518BAC0E47F264F6781A92BCD840FE197D807AF550D2B1A1796E83512114B971ACAC2F4D281105C93387BDF957AB6643684B6AE0547CCDFBEA4D45D967CA18A0E415EA6AF3492C079CE3BA5557BC4C1B92AEAB9FD92232C4CCF00523BCFB57B10F9267AFE980892EA6157299D429D9025F68AB977C031503FF77AEDA8DFBBAB86C3AE11A602FBB160A0E2F858712A2AC1FBD8DEB12E178E098441644BD6DC46A6706CB772A177C47B93919AF34CC8D6530E63C50C890463D2A480A356C6762BF2489C164E105CBA914F0DE04668D8E33D1&sign=BE4683939A325AEEEC4EB1478EB49CCB1DC42170 (Caused by NewConnectionError('<urllib3.connection.HTTPSConnection object at 0x7f1ee13bc810>: Failed to establish a new connection: [Errno 101] Network is unreachable'))
### 执行结果
- **登录状态**: 登录失败
- **签到结果**: 

## 账户2
登录过程出错: HTTPSConnectionPool(host='open.e.189.cn', port=443): Max retries exceeded with url: /api/logbox/oauth2/autoLogin.do?appId=cloud&version=v1.1&clientType=20010&format=redirect&paras=6D932D981C4EFE49970A13C8C2A35BDA4C53BF79191D5034D63475D4ECED2D1AFF04A3C7E287225B3EFA1FD99B39C1CCE113BE29D11C36CBDC0069020BA00AB070B0753F3AB930EAFFE125A6A3AF42387846C8BE8F86A50A8CE948682C059A156CAC25B995D2779262998C124BE787DB28E1A01001E5AA9BB30162E8E950CE253FB0DF908A0BD783A91C505AF021F84C29B9CE442A6348C70B4905B343B6CBB3901047CD45A9F9FC1C55468B4576906B077CF9353577372C3A81D9D16913D36040B2C458AC2BECFBC58D8D9C7ACCB11273DD1367919B8FC5CFFCA2360D8EB3E3E42CE7D5C57CCF869FCB53413FD1BB2FBE2DAAF5DAB9D56AE7ADA9C459C6C42B68F859651D8658A25BAC778ABA7D8F1FBF687BFE5627BF747AD4C60ADBEA192262584DE30BB50B4728AB24BD45016C0D2382CE9D66B721FE16807DB54D9117FC0EF22F4185484A5ADEDAF5BD668A529875FFAAB7A111CCF823903C9132ADE91BD8612DCF7E160BE2DB6BA73A462677AE4594C8D6E2FB4BD7A9FB24213F56B7402107C34C36C67FDC079CDE658AEBEE8CBF2D7EF9D89D671C711F1B11197C42364DE14A636684CA2FDE98132455AC728CE77D9D0A26DF50B602700C7EC5E7D373B0D8DF6B84BC9DE49BDCC3611CE9A594EF767097A612F93969588A92F599D6DA11A952D2B9A53BF4779AEF498B75A59C57CC14190A090AE8E037907520CA9AAA2353B5A626980A5627E2B9E0862904058DEE3BD8A7F252B0&sign=8C4E46EA83E0FB9EB2B15FC4E67D251BB366A2CA (Caused by NewConnectionError('<urllib3.connection.HTTPSConnection object at 0x7f1ee13bffd0>: Failed to establish a new connection: [Errno 101] Network is unreachable'))
### 执行结果
- **登录状态**: 登录失败
- **签到结果**: 

## 账户3
登录过程出错: HTTPSConnectionPool(host='open.e.189.cn', port=443): Max retries exceeded with url: /api/logbox/oauth2/autoLogin.do?appId=cloud&version=v1.1&clientType=20010&format=redirect&paras=BE76DF7A39FF2B154D6258080534609F51590EFE939115929C4E2C478D9CBF92F03D6F94EEF009C7EDB073AB034DC2FF5E9D78C4062CE58FEB7315864E1CC90F8727440578FCECAF6F610B262CCC940BA24D14E2824F2F4E4E3403A6E976C07D3CCA9506F6337445ECEB872A5779BD36C4974DECF073DD00BFB65139BC0A658C835B17098FFA266C32CF820F1504E8F9661538BED6FC97A05714C16DA42EEE6C61BFBBF670CA7B7349546084A7D46D6924737561BD13808F624AE03538A14A9B66726699868524D8414BC5F6C15BA579D7BAA7D1A2F30EB0BEF85E1BC5DD11247925516C269DB11E93C7382856AE4D423C6CCCF47500C76DF9070D81A9B024D90B7BF58A066A0E26BF368D66FA906FDDA2FDE71799E569A2B868202DDDBE73418085F4D85F1EAD5F1A0ECA907710120B13E2809E5FF595110053679A5C65F71E5EED345982D49F49EC9B30DC0A5C3390D0C2703D51C64C6FA7C4E7909469D7119987221BDCA361D0C45A49EBB9B6F31B59F7388035A35B3189E48F77482F95DCD6223DB18E6899DC20D8B6BEC14EF13844193142526F213204E0A54C99EEF0424DF3D9590BEF56F036425719AB39EFA87751036F0B0F862993FF464AD161085D5D881608FA40A20E327809CEED9050632E47DC67117BE43A4EDBD6D56F6A22FC12A6C3FF4E35E6B6435512214A426615E4902266B135CCC40D97D1C2B56091129F473C9AC93B54684F8E3B86E32AA17BC5DFB3149F6A0AEA&sign=5FA89D4C9BE4963DF60C649B32253F97EEFF80EF (Caused by NewConnectionError('<urllib3.connection.HTTPSConnection object at 0x7f1ee13aa810>: Failed to establish a new connection: [Errno 101] Network is unreachable'))
### 执行结果
- **登录状态**: 登录失败
- **签到结果**: 

---
## 执行统计
- **结束时间**: 2025-07-24 22:08:32
- **运行时长**: 819.90 秒

✅ **所有账户处理完成！**
